Workbook

Sheet ИЗ ОСНОВЫ НОМЕНКЛАТУР
A1: КАТЕГОРИЯ | B1: КАТ-2 | C1: ПОДКАТЕГОРИЯ | D1: Номенклатура | E1: КАТЕГОРИЯ | F1: КАТ-2
G2: price | H2: abc
A3: Кромочные материалы | E3: Кромочные материалы | G3: #N/A | H3: C
A4: Кромочные материалы | C4: Кромка ПВХ | E4: Кромочные материалы | G4: #N/A | H4: C
A5: Кромочные материалы | B5: Кромка ПВХ Китай | C5: Кромка ПВХ Китай | E5: Кромочные материалы | F5: Кромка ПВХ Китай | G5: #N/A | H5: C
A6: Кромочные материалы | B6: Кромка ПВХ Китай | C6: 19*0,8мм ПВХ | E6: Кромочные материалы | F6: Кромка ПВХ Китай | G6: #N/A | H6: C
A7: Кромочные материалы | B7: Кромка ПВХ Китай | C7: 19*0,8мм ПВХ | D7: 19*0,8мм ПВХ Белый AN | E7: Кромочные материалы | F7: Кромка ПВХ Китай | G7: 18.061539 | H7: A
A8: Кромочные материалы | B8: Кромка ПВХ Китай | C8: 19*0,8мм ПВХ | D8: 19*0,8мм ПВХ Дуб сонома AN | E8: Кромочные материалы | F8: Кромка ПВХ Китай | G8: 25.037059 | H8: A
A9: Кромочные материалы | B9: Кромка ПВХ Китай | C9: 19*0,8мм ПВХ | D9: 19*0,8мм ПВХ Дуб Вотан AN | E9: Кромочные материалы | F9: Кромка ПВХ Китай | G9: 26.14571 | H9: A
A10: Кромочные материалы | B10: Кромка ПВХ Китай | C10: 19*0,8мм ПВХ | D10: 19*0,8мм ПВХ Серый SJ | E10: Кромочные материалы | F10: Кромка ПВХ Китай | G10: 18.169597 | H10: A
A11: Кромочные материалы | B11: Кромка ПВХ Китай | C11: 19*0,8мм ПВХ | D11: 19*0,8мм ПВХ Тэффи SJ | E11: Кромочные материалы | F11: Кромка ПВХ Китай | G11: 17.758084 | H11: A
A12: Кромочные материалы | B12: Кромка ПВХ Китай | C12: 19*0,8мм ПВХ | D12: 19*0,8мм ПВХ Тэффи AN | E12: Кромочные материалы | F12: Кромка ПВХ Китай | G12: 21.594333 | H12: A
A13: Кромочные материалы | B13: Кромка ПВХ Китай | C13: 19*0,8мм ПВХ | D13: 19*0,8мм ПВХ Черный AN | E13: Кромочные материалы | F13: Кромка ПВХ Китай | G13: 18.815736 | H13: A
A14: Кромочные материалы | B14: Кромка ПВХ Китай | C14: 19*0,8мм ПВХ | D14: 19*0,8мм ПВХ Белый (Гладкий) AN | E14: Кромочные материалы | F14: Кромка ПВХ Китай | G14: 22.252896 | H14: A
A15: Кромочные материалы | B15: Кромка ПВХ Китай | C15: 19*0,8мм ПВХ | D15: 19*0,8мм ПВХ Вулканический серый AN | E15: Кромочные материалы | F15: Кромка ПВХ Китай | G15: 23.109631 | H15: A
A16: Кромочные материалы | B16: Кромка ПВХ Китай | C16: 19*0,8мм ПВХ | D16: 19*0,8мм ПВХ Антрацит AN | E16: Кромочные материалы | F16: Кромка ПВХ Китай | G16: 19.798543 | H16: A
A17: Кромочные материалы | B17: Кромка ПВХ Китай | C17: 19*0,8мм ПВХ | D17: 19*0,8мм ПВХ Ясень шимо светлый AN | E17: Кромочные материалы | F17: Кромка ПВХ Китай | G17: 25.043404 | H17: A
A18: Кромочные материалы | B18: Кромка ПВХ Китай | C18: 19*0,8мм ПВХ | D18: 19*0,8мм ПВХ Серый AN | E18: Кромочные материалы | F18: Кромка ПВХ Китай | G18: 20.563563 | H18: A
... A213: Кромочные материалы | B213: Кромка ПВХ Китай | C213: 19*0,8мм ПВХ | D213: 19*0,8мм ПВХ Ена AN | E213: Кромочные материалы | F213: Кромка ПВХ Китай | G213: 71.517488 | H213: C
A214: Кромочные материалы | B214: Кромка ПВХ Китай | C214: 19*1,5мм ПВХ | E214: Кромочные материалы | F214: Кромка ПВХ Китай | G214: #N/A | H214: C
A215: Кромочные материалы | B215: Кромка ПВХ Китай | D215: 19*1,5мм ПВХ Белый AN | E215: Кромочные материалы | F215: Кромка ПВХ Китай | G215: 37.480355 | H215: A
A216: Кромочные материалы | B216: Кромка ПВХ Китай | D216: 19*1,5мм ПВХ Ясень шимо светлый SJ | E216: Кромочные материалы | F216: Кромка ПВХ Китай | G216: 37.117488 | H216: A
A217: Кромочные материалы | B217: Кромка ПВХ Китай | D217: 19*1,5мм ПВХ Дуб вотан AN | E217: Кромочные материалы | F217: Кромка ПВХ Китай | G217: 42.737958 | H217: A
A218: Кромочные материалы | B218: Кромка ПВХ Китай | D218: 19*1,5мм ПВХ Ясень шимо светлый AN | E218: Кромочные материалы | F218: Кромка ПВХ Китай | G218: 43.848085 | H218: A
A219: Кромочные материалы | B219: Кромка ПВХ Китай | D219: 19*1,5мм ПВХ Бежевый AN | E219: Кромочные материалы | F219: Кромка ПВХ Китай | G219: 44.268372 | H219: A
A220: Кромочные материалы | B220: Кромка ПВХ Китай | D220: 19*1,5мм ПВХ Ясень шимо темный AN | E220: Кромочные материалы | F220: Кромка ПВХ Китай | G220: 48.091197 | H220: A
A221: Кромочные материалы | B221: Кромка ПВХ Китай | D221: 19*1,5мм ПВХ Дуб Сонома AN | E221: Кромочные материалы | F221: Кромка ПВХ Китай | G221: 46.496593 | H221: A
A222: Кромочные материалы | B222: Кромка ПВХ Китай | D222: 19*1,5мм ПВХ Ясень шимо темный SJ | E222: Кромочные материалы | F222: Кромка ПВХ Китай | G222: 42.618154 | H222: A
A223: Кромочные материалы | B223: Кромка ПВХ Китай | D223: 19*1,5мм ПВХ Серый AN | E223: Кромочные материалы | F223: Кромка ПВХ Китай | G223: 38.867261 | H223: A
A224: Кромочные материалы | B224: Кромка ПВХ Китай | D224: 19*1,5мм ПВХ Дуб сонома SJ | E224: Кромочные материалы | F224: Кромка ПВХ Китай | G224: 41.768855 | H224: A
A225: Кромочные материалы | B225: Кромка ПВХ Китай | D225: 19*1,5мм ПВХ Антрацит AN | E225: Кромочные материалы | F225: Кромка ПВХ Китай | G225: 39.1291 | H225: B
A226: Кромочные материалы | B226: Кромка ПВХ Китай | D226: 19*1,5мм ПВХ Алюминий AN | E226: Кромочные материалы | F226: Кромка ПВХ Китай | G226: 49.389295 | H226: B
... A262: Кромочные материалы | B262: Кромка ПВХ Китай | D262: 19*1,5мм ПВХ Дуб честерфилд AN | E262: Кромочные материалы | F262: Кромка ПВХ Китай | G262: 51.0748 | H262: C
A263: Кромочные материалы | B263: Кромка ПВХ Китай | C263: 36*1,5мм ПВХ | E263: Кромочные материалы | F263: Кромка ПВХ Китай | G263: #N/A | H263: C
A264: Кромочные материалы | B264: Кромка ПВХ Китай | D264: 36*1,5мм ПВХ Белый AN | E264: Кромочные материалы | F264: Кромка ПВХ Китай | G264: 68.679877 | H264: A
A265: Кромочные материалы | B265: Кромка ПВХ Китай | D265: 36*1,5мм ПВХ Дуб Вотан AN | E265: Кромочные материалы | F265: Кромка ПВХ Китай | G265: 82.057037 | H265: B
A266: Кромочные материалы | B266: Кромка ПВХ Китай | D266: 36*1,5мм ПВХ Дуб Сонома AN | E266: Кромочные материалы | F266: Кромка ПВХ Китай | G266: 89.909067 | H266: B
A267: Кромочные материалы | B267: Кромка ПВХ Китай | D267: 36*1,5мм ПВХ Ясень шимо светлый AN | E267: Кромочные материалы | F267: Кромка ПВХ Китай | G267: 92.001398 | H267: B
A268: Кромочные материалы | B268: Кромка ПВХ Китай | D268: 36*1,5мм ПВХ Белый SJ | E268: Кромочные материалы | F268: Кромка ПВХ Китай | G268: 62.673169 | H268: B
A269: Кромочные материалы | B269: Кромка ПВХ Китай | D269: 36*1,5мм ПВХ Черный AN | E269: Кромочные материалы | F269: Кромка ПВХ Китай | G269: 82.680723 | H269: B
...

Sheet ОСТАТКИ
A1: Номенклатура | D1: 4 Склад фурнитуры АЗМ Шымкент "Овощная база" | E1: 6 Склад фурнитуры "Овощная база" Магазин | G1: АО Склад Фурнитура TRADE | I1: База Склад Фурнитура Комплект | J1: Барыс Склад Фурнитура TRADE | K1: Казыбаева Склад Фурнитура TRADE | L1: Магазин фурнитуры | M1: склад фурнитура № 1 | N1: ТД Казыбаева ФУРНИТУРА магазин | O1: Итого | T1: 4 Склад фурнитуры АЗМ Шымкент "Овощная база" | U1: 6 Склад фурнитуры "Овощная база" Магазин | W1: АО Склад Фурнитура TRADE | Y1: База Склад Фурнитура Комплект | Z1: Барыс Склад Фурнитура TRADE | AA1: Казыбаева Склад Фурнитура TRADE | AB1: Магазин фурнитуры | AC1: склад фурнитура № 1 | AD1: ТД Казыбаева ФУРНИТУРА магазин
A3: =A1=A5 -> TRUE | B3: =B1=B5 -> TRUE | C3: =C1=C5 -> TRUE | D3: =D1=D5 -> TRUE | E3: =E1=E5 -> TRUE | F3: =F1=F5 -> TRUE | G3: =G1=G5 -> TRUE | H3: =H1=H5 -> TRUE | ... O3: =O1=O5 -> TRUE | T3: =T1=T5 -> TRUE | U3: =U1=U5 -> TRUE | V3: =V1=V5 -> TRUE | W3: =W1=W5 -> TRUE | X3: =X1=X5 -> TRUE | Y3: =Y1=Y5 -> TRUE | Z3: =Z1=Z5 -> TRUE | AA3: =AA1=AA5 -> TRUE | ... AD3: =AD1=AD5 -> TRUE
T4: сумм остатков
A5: Номенклатура | D5: 4 Склад фурнитуры АЗМ Шымкент "Овощная база" | E5: 6 Склад фурнитуры "Овощная база" Магазин | G5: АО Склад Фурнитура TRADE | I5: База Склад Фурнитура Комплект | J5: Барыс Склад Фурнитура TRADE | K5: Казыбаева Склад Фурнитура TRADE | L5: Магазин фурнитуры | M5: склад фурнитура № 1 | N5: ТД Казыбаева ФУРНИТУРА магазин | O5: Итого | T5: 4 Склад фурнитуры АЗМ Шымкент "Овощная база" | U5: 6 Склад фурнитуры "Овощная база" Магазин | W5: АО Склад Фурнитура TRADE | Y5: База Склад Фурнитура Комплект | Z5: Барыс Склад Фурнитура TRADE | AA5: Казыбаева Склад Фурнитура TRADE | AB5: Магазин фурнитуры | AC5: склад фурнитура № 1 | AD5: ТД Казыбаева ФУРНИТУРА магазин | AE5: тотал ост по СС
D6: Количество | E6: Количество | G6: Количество | I6: Количество | J6: Количество | K6: Количество | L6: Количество | M6: Количество | N6: Количество | O6: Количество | T6: Количество | U6: Количество | W6: Количество | Y6: Количество | Z6: Количество | AA6: Количество | AB6: Количество | AC6: Количество | AD6: Количество
D7: Конечный остаток | E7: Конечный остаток | G7: Конечный остаток | I7: Конечный остаток | J7: Конечный остаток | K7: Конечный остаток | L7: Конечный остаток | M7: Конечный остаток | N7: Конечный остаток | O7: Конечный остаток | P7: КАТ | Q7: КАТ-2 | R7: ЦЕНА | S7: ABC | T7: Конечный остаток | U7: Конечный остаток | W7: Конечный остаток | Y7: Конечный остаток | Z7: Конечный остаток | AA7: Конечный остаток | AB7: Конечный остаток | AC7: Конечный остаток | AD7: Конечный остаток
A8: 1,5*25мм Венге цаво 3354 PR | J8: 180 | K8: 300 | O8: 480 | P8: =VLOOKUP(A8,'ИЗ ОСНОВЫ НОМЕНКЛАТУР'!D:E,2,0) -> Кромочные материалы | Q8: =VLOOKUP(A8,'ИЗ ОСНОВЫ НОМЕНКЛАТУР'!D:F,3,0) -> Кромка ПВХ Россия | R8: =VLOOKUP(A:A,'ИЗ ОСНОВЫ НОМЕНКЛАТУР'!D:G,4,0) -> 72.831 | S8: =VLOOKUP(A:A,'ИЗ ОСНОВЫ НОМЕНКЛАТУР'!D:H,5,0) -> C | T8: =$R8*D8 -> 0 | U8: =$R8*E8 -> 0 | V8: =$R8*F8 -> 0 | W8: =$R8*G8 -> 0 | X8: =$R8*H8 -> 0 | Y8: =$R8*I8 -> 0 | Z8: =$R8*J8 -> 13109.58 | AA8: =$R8*K8 -> 21849.3 | ... AD8: =$R8*N8 -> 0 | AE8: =SUM(T8:AD8) -> 34958.88
A9: 1,5*25мм Дуб белый Craft К001 | J9: 168 | O9: 168 | P9: =VLOOKUP(A9,'ИЗ ОСНОВЫ НОМЕНКЛАТУР'!D:E,2,0) -> Кромочные материалы | Q9: =VLOOKUP(A9,'ИЗ ОСНОВЫ НОМЕНКЛАТУР'!D:F,3,0) -> Кромка ПВХ Россия | R9: =VLOOKUP(A:A,'ИЗ ОСНОВЫ НОМЕНКЛАТУР'!D:G,4,0) -> 72.428571 | S9: =VLOOKUP(A:A,'ИЗ ОСНОВЫ НОМЕНКЛАТУР'!D:H,5,0) -> C | T9: =$R9*D9 -> 0 | U9: =$R9*E9 -> 0 | V9: =$R9*F9 -> 0 | W9: =$R9*G9 -> 0 | X9: =$R9*H9 -> 0 | Y9: =$R9*I9 -> 0 | Z9: =$R9*J9 -> 12168 | AA9: =$R9*K9 -> 0 | ... AD9: =$R9*N9 -> 0 | AE9: =SUM(T9:AD9) -> 12168
A10: 1,5*25мм Дуб Венге 6495 PR | J10: 300 | K10: 600 | O10: 900 | P10: =VLOOKUP(A10,'ИЗ ОСНОВЫ НОМЕНКЛАТУР'!D:E,2,0) -> Кромочные материалы | Q10: =VLOOKUP(A10,'ИЗ ОСНОВЫ НОМЕНКЛАТУР'!D:F,3,0) -> Кромка ПВХ Россия | R10: =VLOOKUP(A:A,'ИЗ ОСНОВЫ НОМЕНКЛАТУР'!D:G,4,0) -> 72.634444 | S10: =VLOOKUP(A:A,'ИЗ ОСНОВЫ НОМЕНКЛАТУР'!D:H,5,0) -> C | T10: =$R10*D10 -> 0 | U10: =$R10*E10 -> 0 | V10: =$R10*F10 -> 0 | W10: =$R10*G10 -> 0 | X10: =$R10*H10 -> 0 | Y10: =$R10*I10 -> 0 | Z10: =$R10*J10 -> 21790.333 | AA10: =$R10*K10 -> 43580.667 | ... AD10: =$R10*N10 -> 0 | AE10: =SUM(T10:AD10) -> 65371
A11: 1,5*25мм Дуб золотой Craft К003 PW | J11: 300 | O11: 300 | P11: =VLOOKUP(A11,'ИЗ ОСНОВЫ НОМЕНКЛАТУР'!D:E,2,0) -> Кромочные материалы | Q11: =VLOOKUP(A11,'ИЗ ОСНОВЫ НОМЕНКЛАТУР'!D:F,3,0) -> Кромка ПВХ Россия | R11: =VLOOKUP(A:A,'ИЗ ОСНОВЫ НОМЕНКЛАТУР'!D:G,4,0) -> 83.213333 | S11: =VLOOKUP(A:A,'ИЗ ОСНОВЫ НОМЕНКЛАТУР'!D:H,5,0) -> C | T11: =$R11*D11 -> 0 | U11: =$R11*E11 -> 0 | V11: =$R11*F11 -> 0 | W11: =$R11*G11 -> 0 | X11: =$R11*H11 -> 0 | Y11: =$R11*I11 -> 0 | Z11: =$R11*J11 -> 24964 | AA11: =$R11*K11 -> 0 | ... AD11: =$R11*N11 -> 0 | AE11: =SUM(T11:AD11) -> 24964
A12: 1,5*25мм Дуб молочный 8622 PR | K12: 400 | O12: 400 | P12: =VLOOKUP(A12,'ИЗ ОСНОВЫ НОМЕНКЛАТУР'!D:E,2,0) -> Кромочные материалы | Q12: =VLOOKUP(A12,'ИЗ ОСНОВЫ НОМЕНКЛАТУР'!D:F,3,0) -> Кромка ПВХ Россия | R12: =VLOOKUP(A:A,'ИЗ ОСНОВЫ НОМЕНКЛАТУР'!D:G,4,0) -> 83.2125 | S12: =VLOOKUP(A:A,'ИЗ ОСНОВЫ НОМЕНКЛАТУР'!D:H,5,0) -> C | T12: =$R12*D12 -> 0 | U12: =$R12*E12 -> 0 | V12: =$R12*F12 -> 0 | W12: =$R12*G12 -> 0 | X12: =$R12*H12 -> 0 | Y12: =$R12*I12 -> 0 | Z12: =$R12*J12 -> 0 | AA12: =$R12*K12 -> 33285 | ... AD12: =$R12*N12 -> 0 | AE12: =SUM(T12:AD12) -> 33285
A13: 1,5*25мм Дуб Сонома светлый 3660 PR | J13: 300 | K13: 600 | O13: 900 | P13: =VLOOKUP(A13,'ИЗ ОСНОВЫ НОМЕНКЛАТУР'!D:E,2,0) -> Кромочные материалы | Q13: =VLOOKUP(A13,'ИЗ ОСНОВЫ НОМЕНКЛАТУР'!D:F,3,0) -> Кромка ПВХ Россия | R13: =VLOOKUP(A:A,'ИЗ ОСНОВЫ НОМЕНКЛАТУР'!D:G,4,0) -> 83.212222 | S13: =VLOOKUP(A:A,'ИЗ ОСНОВЫ НОМЕНКЛАТУР'!D:H,5,0) -> C | T13: =$R13*D13 -> 0 | U13: =$R13*E13 -> 0 | V13: =$R13*F13 -> 0 | W13: =$R13*G13 -> 0 | X13: =$R13*H13 -> 0 | Y13: =$R13*I13 -> 0 | Z13: =$R13*J13 -> 24963.667 | AA13: =$R13*K13 -> 49927.333 | ... AD13: =$R13*N13 -> 0 | AE13: =SUM(T13:AD13) -> 74891
A14: 1,5*25мм Ясень анкор светлый 4780 PR | J14: 200 | O14: 200 | P14: =VLOOKUP(A14,'ИЗ ОСНОВЫ НОМЕНКЛАТУР'!D:E,2,0) -> Кромочные материалы | Q14: =VLOOKUP(A14,'ИЗ ОСНОВЫ НОМЕНКЛАТУР'!D:F,3,0) -> Кромка ПВХ Россия | R14: =VLOOKUP(A:A,'ИЗ ОСНОВЫ НОМЕНКЛАТУР'!D:G,4,0) -> 72.43 | S14: =VLOOKUP(A:A,'ИЗ ОСНОВЫ НОМЕНКЛАТУР'!D:H,5,0) -> C | T14: =$R14*D14 -> 0 | U14: =$R14*E14 -> 0 | V14: =$R14*F14 -> 0 | W14: =$R14*G14 -> 0 | X14: =$R14*H14 -> 0 | Y14: =$R14*I14 -> 0 | Z14: =$R14*J14 -> 14486 | AA14: =$R14*K14 -> 0 | ... AD14: =$R14*N14 -> 0 | AE14: =SUM(T14:AD14) -> 14486
A15: 1,5*25мм Ясень Анкор темный 4779 PR | K15: 600 | O15: 600 | P15: =VLOOKUP(A15,'ИЗ ОСНОВЫ НОМЕНКЛАТУР'!D:E,2,0) -> Кромочные материалы | Q15: =VLOOKUP(A15,'ИЗ ОСНОВЫ НОМЕНКЛАТУР'!D:F,3,0) -> Кромка ПВХ Россия | R15: =VLOOKUP(A:A,'ИЗ ОСНОВЫ НОМЕНКЛАТУР'!D:G,4,0) -> 69.646667 | S15: =VLOOKUP(A:A,'ИЗ ОСНОВЫ НОМЕНКЛАТУР'!D:H,5,0) -> C | T15: =$R15*D15 -> 0 | U15: =$R15*E15 -> 0 | V15: =$R15*F15 -> 0 | W15: =$R15*G15 -> 0 | X15: =$R15*H15 -> 0 | Y15: =$R15*I15 -> 0 | Z15: =$R15*J15 -> 0 | AA15: =$R15*K15 -> 41788 | ... AD15: =$R15*N15 -> 0 | AE15: =SUM(T15:AD15) -> 41788
A16: 19*0,4мм Atellier Темный 4299 SU | J16: 3000 | K16: 3800 | O16: 6800 | P16: =VLOOKUP(A16,'ИЗ ОСНОВЫ НОМЕНКЛАТУР'!D:E,2,0) -> Кромочные материалы | Q16: =VLOOKUP(A16,'ИЗ ОСНОВЫ НОМЕНКЛАТУР'!D:F,3,0) -> Кромка ПВХ Россия | R16: =VLOOKUP(A:A,'ИЗ ОСНОВЫ НОМЕНКЛАТУР'!D:G,4,0) -> 20.351 | S16: =VLOOKUP(A:A,'ИЗ ОСНОВЫ НОМЕНКЛАТУР'!D:H,5,0) -> C | T16: =$R16*D16 -> 0 | U16: =$R16*E16 -> 0 | V16: =$R16*F16 -> 0 | W16: =$R16*G16 -> 0 | X16: =$R16*H16 -> 0 | Y16: =$R16*I16 -> 0 | Z16: =$R16*J16 -> 61053 | AA16: =$R16*K16 -> 77333.8 | ... AD16: =$R16*N16 -> 0 | AE16: =SUM(T16:AD16) -> 138386.8
A17: 19*0,4мм Алюминий ПВХ MS | N17: 365 | O17: 365 | P17: =VLOOKUP(A17,'ИЗ ОСНОВЫ НОМЕНКЛАТУР'!D:E,2,0) -> Кромочные материалы | Q17: =VLOOKUP(A17,'ИЗ ОСНОВЫ НОМЕНКЛАТУР'!D:F,3,0) -> Распродажа кромка | R17: =VLOOKUP(A:A,'ИЗ ОСНОВЫ НОМЕНКЛАТУР'!D:G,4,0) -> 8.5061321 | S17: =VLOOKUP(A:A,'ИЗ ОСНОВЫ НОМЕНКЛАТУР'!D:H,5,0) -> C | T17: =$R17*D17 -> 0 | U17: =$R17*E17 -> 0 | V17: =$R17*F17 -> 0 | W17: =$R17*G17 -> 0 | X17: =$R17*H17 -> 0 | Y17: =$R17*I17 -> 0 | Z17: =$R17*J17 -> 0 | AA17: =$R17*K17 -> 0 | ... AD17: =$R17*N17 -> 3104.7382 | AE17: =SUM(T17:AD17) -> 3104.7382
A18: 19*0,4мм Артвуд светлый К083 SN | J18: 1800 | K18: 5000 | O18: 6800 | P18: =VLOOKUP(A18,'ИЗ ОСНОВЫ НОМЕНКЛАТУР'!D:E,2,0) -> Кромочные материалы | Q18: =VLOOKUP(A18,'ИЗ ОСНОВЫ НОМЕНКЛАТУР'!D:F,3,0) -> Кромка ПВХ Россия | R18: =VLOOKUP(A:A,'ИЗ ОСНОВЫ НОМЕНКЛАТУР'!D:G,4,0) -> 20.47785 | S18: =VLOOKUP(A:A,'ИЗ ОСНОВЫ НОМЕНКЛАТУР'!D:H,5,0) -> C | T18: =$R18*D18 -> 0 | U18: =$R18*E18 -> 0 | V18: =$R18*F18 -> 0 | W18: =$R18*G18 -> 0 | X18: =$R18*H18 -> 0 | Y18: =$R18*I18 -> 0 | Z18: =$R18*J18 -> 36860.13 | AA18: =$R18*K18 -> 102389.25 | ... AD18: =$R18*N18 -> 0 | AE18: =SUM(T18:AD18) -> 139249.38
A19: 19*0,4мм Артвуд темный К084 SN | J19: 600 | K19: 4000 | O19: 4600 | P19: =VLOOKUP(A19,'ИЗ ОСНОВЫ НОМЕНКЛАТУР'!D:E,2,0) -> Кромочные материалы | Q19: =VLOOKUP(A19,'ИЗ ОСНОВЫ НОМЕНКЛАТУР'!D:F,3,0) -> Кромка ПВХ Россия | R19: =VLOOKUP(A:A,'ИЗ ОСНОВЫ НОМЕНКЛАТУР'!D:G,4,0) -> 20.43345 | S19: =VLOOKUP(A:A,'ИЗ ОСНОВЫ НОМЕНКЛАТУР'!D:H,5,0) -> C | T19: =$R19*D19 -> 0 | U19: =$R19*E19 -> 0 | V19: =$R19*F19 -> 0 | W19: =$R19*G19 -> 0 | X19: =$R19*H19 -> 0 | Y19: =$R19*I19 -> 0 | Z19: =$R19*J19 -> 12260.07 | AA19: =$R19*K19 -> 81733.8 | ... AD19: =$R19*N19 -> 0 | AE19: =SUM(T19:AD19) -> 93993.87
A20: 19*0,4мм Зеленый Лайм 5519 BS | J20: 5400 | O20: 5400 | P20: =VLOOKUP(A20,'ИЗ ОСНОВЫ НОМЕНКЛАТУР'!D:E,2,0) -> Кромочные материалы | Q20: =VLOOKUP(A20,'ИЗ ОСНОВЫ НОМЕНКЛАТУР'!D:F,3,0) -> Кромка ПВХ Россия | R20: =VLOOKUP(A:A,'ИЗ ОСНОВЫ НОМЕНКЛАТУР'!D:G,4,0) -> 12.557 | S20: =VLOOKUP(A:A,'ИЗ ОСНОВЫ НОМЕНКЛАТУР'!D:H,5,0) -> C | T20: =$R20*D20 -> 0 | U20: =$R20*E20 -> 0 | V20: =$R20*F20 -> 0 | W20: =$R20*G20 -> 0 | X20: =$R20*H20 -> 0 | Y20: =$R20*I20 -> 0 | Z20: =$R20*J20 -> 67807.8 | AA20: =$R20*K20 -> 0 | ... AD20: =$R20*N20 -> 0 | AE20: =SUM(T20:AD20) -> 67807.8
A21: 19*0,4мм Клен Танзау 0375 PR | J21: 2200 | O21: 2200 | P21: =VLOOKUP(A21,'ИЗ ОСНОВЫ НОМЕНКЛАТУР'!D:E,2,0) -> Кромочные материалы | Q21: =VLOOKUP(A21,'ИЗ ОСНОВЫ НОМЕНКЛАТУР'!D:F,3,0) -> Кромка ПВХ Россия | R21: =VLOOKUP(A:A,'ИЗ ОСНОВЫ НОМЕНКЛАТУР'!D:G,4,0) -> 17.753 | S21: =VLOOKUP(A:A,'ИЗ ОСНОВЫ НОМЕНКЛАТУР'!D:H,5,0) -> C | T21: =$R21*D21 -> 0 | U21: =$R21*E21 -> 0 | V21: =$R21*F21 -> 0 | W21: =$R21*G21 -> 0 | X21: =$R21*H21 -> 0 | Y21: =$R21*I21 -> 0 | Z21: =$R21*J21 -> 39056.6 | AA21: =$R21*K21 -> 0 | ... AD21: =$R21*N21 -> 0 | AE21: =SUM(T21:AD21) -> 39056.6
A22: 19*0,4мм Королевский Синий 0125 PE | J22: 4600 | O22: 4600 | P22: =VLOOKUP(A22,'ИЗ ОСНОВЫ НОМЕНКЛАТУР'!D:E,2,0) -> Кромочные материалы | Q22: =VLOOKUP(A22,'ИЗ ОСНОВЫ НОМЕНКЛАТУР'!D:F,3,0) -> Кромка ПВХ Россия | R22: =VLOOKUP(A:A,'ИЗ ОСНОВЫ НОМЕНКЛАТУР'!D:G,4,0) -> 14.346957 | S22: =VLOOKUP(A:A,'ИЗ ОСНОВЫ НОМЕНКЛАТУР'!D:H,5,0) -> C | T22: =$R22*D22 -> 0 | U22: =$R22*E22 -> 0 | V22: =$R22*F22 -> 0 | W22: =$R22*G22 -> 0 | X22: =$R22*H22 -> 0 | Y22: =$R22*I22 -> 0 | Z22: =$R22*J22 -> 65996 | AA22: =$R22*K22 -> 0 | ... AD22: =$R22*N22 -> 0 | AE22: =SUM(T22:AD22) -> 65996
A23: 19*0,4мм Красный Чили 7113 PE | K23: 6800 | O23: 6800 | P23: =VLOOKUP(A23,'ИЗ ОСНОВЫ НОМЕНКЛАТУР'!D:E,2,0) -> Кромочные материалы | Q23: =VLOOKUP(A23,'ИЗ ОСНОВЫ НОМЕНКЛАТУР'!D:F,3,0) -> Кромка ПВХ Россия | R23: =VLOOKUP(A:A,'ИЗ ОСНОВЫ НОМЕНКЛАТУР'!D:G,4,0) -> 12.557 | S23: =VLOOKUP(A:A,'ИЗ ОСНОВЫ НОМЕНКЛАТУР'!D:H,5,0) -> C | T23: =$R23*D23 -> 0 | U23: =$R23*E23 -> 0 | V23: =$R23*F23 -> 0 | W23: =$R23*G23 -> 0 | X23: =$R23*H23 -> 0 | Y23: =$R23*I23 -> 0 | Z23: =$R23*J23 -> 0 | AA23: =$R23*K23 -> 85387.6 | ... AD23: =$R23*N23 -> 0 | AE23: =SUM(T23:AD23) -> 85387.6
A24: 19*0,4мм Оранжевый 0132 PE | J24: 3900 | O24: 3900 | P24: =VLOOKUP(A24,'ИЗ ОСНОВЫ НОМЕНКЛАТУР'!D:E,2,0) -> Кромочные материалы | Q24: =VLOOKUP(A24,'ИЗ ОСНОВЫ НОМЕНКЛАТУР'!D:F,3,0) -> Кромка ПВХ Россия | R24: =VLOOKUP(A:A,'ИЗ ОСНОВЫ НОМЕНКЛАТУР'!D:G,4,0) -> 12.557 | S24: =VLOOKUP(A:A,'ИЗ ОСНОВЫ НОМЕНКЛАТУР'!D:H,5,0) -> C | T24: =$R24*D24 -> 0 | U24: =$R24*E24 -> 0 | V24: =$R24*F24 -> 0 | W24: =$R24*G24 -> 0 | X24: =$R24*H24 -> 0 | Y24: =$R24*I24 -> 0 | Z24: =$R24*J24 -> 48972.3 | AA24: =$R24*K24 -> 0 | ... AD24: =$R24*N24 -> 0 | AE24: =SUM(T24:AD24) -> 48972.3
A25: 19*0,4мм Орех Гепланкт 5648 PR | J25: 5800 | K25: 6400 | O25: 12200 | P25: =VLOOKUP(A25,'ИЗ ОСНОВЫ НОМЕНКЛАТУР'!D:E,2,0) -> Кромочные материалы | Q25: =VLOOKUP(A25,'ИЗ ОСНОВЫ НОМЕНКЛАТУР'!D:F,3,0) -> Кромка ПВХ Россия | R25: =VLOOKUP(A:A,'ИЗ ОСНОВЫ НОМЕНКЛАТУР'!D:G,4,0) -> 17.720967 | S25: =VLOOKUP(A:A,'ИЗ ОСНОВЫ НОМЕНКЛАТУР'!D:H,5,0) -> C | T25: =$R25*D25 -> 0 | U25: =$R25*E25 -> 0 | V25: =$R25*F25 -> 0 | W25: =$R25*G25 -> 0 | X25: =$R25*H25 -> 0 | Y25: =$R25*I25 -> 0 | Z25: =$R25*J25 -> 102781.61 | AA25: =$R25*K25 -> 113414.19 | ... AD25: =$R25*N25 -> 0 | AE25: =SUM(T25:AD25) -> 216195.79
A26: 19*0,4мм Орех экко 9459 PR | J26: 4400 | O26: 4400 | P26: =VLOOKUP(A26,'ИЗ ОСНОВЫ НОМЕНКЛАТУР'!D:E,2,0) -> Кромочные материалы | Q26: =VLOOKUP(A26,'ИЗ ОСНОВЫ НОМЕНКЛАТУР'!D:F,3,0) -> Кромка ПВХ Россия | R26: =VLOOKUP(A:A,'ИЗ ОСНОВЫ НОМЕНКЛАТУР'!D:G,4,0) -> 20.283636 | S26: =VLOOKUP(A:A,'ИЗ ОСНОВЫ НОМЕНКЛАТУР'!D:H,5,0) -> C | T26: =$R26*D26 -> 0 | U26: =$R26*E26 -> 0 | V26: =$R26*F26 -> 0 | W26: =$R26*G26 -> 0 | X26: =$R26*H26 -> 0 | Y26: =$R26*I26 -> 0 | Z26: =$R26*J26 -> 89248 | AA26: =$R26*K26 -> 0 | ... AD26: =$R26*N26 -> 0 | AE26: =SUM(T26:AD26) -> 89248
A27: 19*0,4мм ПВХ Антрацит AN | N27: 21 | O27: 21 | P27: =VLOOKUP(A27,'ИЗ ОСНОВЫ НОМЕНКЛАТУР'!D:E,2,0) -> Кромочные материалы | Q27: =VLOOKUP(A27,'ИЗ ОСНОВЫ НОМЕНКЛАТУР'!D:F,3,0) -> Кромка ПВХ Китай | R27: =VLOOKUP(A:A,'ИЗ ОСНОВЫ НОМЕНКЛАТУР'!D:G,4,0) -> 11.281404 | S27: =VLOOKUP(A:A,'ИЗ ОСНОВЫ НОМЕНКЛАТУР'!D:H,5,0) -> C | T27: =$R27*D27 -> 0 | U27: =$R27*E27 -> 0 | V27: =$R27*F27 -> 0 | W27: =$R27*G27 -> 0 | X27: =$R27*H27 -> 0 | Y27: =$R27*I27 -> 0 | Z27: =$R27*J27 -> 0 | AA27: =$R27*K27 -> 0 | ... AD27: =$R27*N27 -> 236.90948 | AE27: =SUM(T27:AD27) -> 236.90948
A28: 19*0,4мм ПВХ Белый AN | N28: 61 | O28: 61 | P28: =VLOOKUP(A28,'ИЗ ОСНОВЫ НОМЕНКЛАТУР'!D:E,2,0) -> Кромочные материалы | Q28: =VLOOKUP(A28,'ИЗ ОСНОВЫ НОМЕНКЛАТУР'!D:F,3,0) -> Кромка ПВХ Китай | R28: =VLOOKUP(A:A,'ИЗ ОСНОВЫ НОМЕНКЛАТУР'!D:G,4,0) -> 11.854472 | S28: =VLOOKUP(A:A,'ИЗ ОСНОВЫ НОМЕНКЛАТУР'!D:H,5,0) -> A | T28: =$R28*D28 -> 0 | U28: =$R28*E28 -> 0 | V28: =$R28*F28 -> 0 | W28: =$R28*G28 -> 0 | X28: =$R28*H28 -> 0 | Y28: =$R28*I28 -> 0 | Z28: =$R28*J28 -> 0 | AA28: =$R28*K28 -> 0 | ... AD28: =$R28*N28 -> 723.12276 | AE28: =SUM(T28:AD28) -> 723.12276
A29: 19*0,4мм ПВХ Белый SD | I29: 284000 | J29: 2000 | K29: 8000 | O29: 294000 | P29: =VLOOKUP(A29,'ИЗ ОСНОВЫ НОМЕНКЛАТУР'!D:E,2,0) -> Кромочные материалы | Q29: =VLOOKUP(A29,'ИЗ ОСНОВЫ НОМЕНКЛАТУР'!D:F,3,0) -> Распродажа кромка | R29: =VLOOKUP(A:A,'ИЗ ОСНОВЫ НОМЕНКЛАТУР'!D:G,4,0) -> 10.5 | S29: =VLOOKUP(A:A,'ИЗ ОСНОВЫ НОМЕНКЛАТУР'!D:H,5,0) -> B | T29: =$R29*D29 -> 0 | U29: =$R29*E29 -> 0 | V29: =$R29*F29 -> 0 | W29: =$R29*G29 -> 0 | X29: =$R29*H29 -> 0 | Y29: =$R29*I29 -> 2982000 | Z29: =$R29*J29 -> 21000 | AA29: =$R29*K29 -> 84000 | ... AD29: =$R29*N29 -> 0 | AE29: =SUM(T29:AD29) -> 3087000
A30: 19*0,4мм ПВХ Белый SJ | J30: 29600 | K30: 13600 | N30: 999 | O30: 44199 | P30: =VLOOKUP(A30,'ИЗ ОСНОВЫ НОМЕНКЛАТУР'!D:E,2,0) -> Кромочные материалы | Q30: =VLOOKUP(A30,'ИЗ ОСНОВЫ НОМЕНКЛАТУР'!D:F,3,0) -> Кромка ПВХ Китай | R30: =VLOOKUP(A:A,'ИЗ ОСНОВЫ НОМЕНКЛАТУР'!D:G,4,0) -> 9.3904509 | S30: =VLOOKUP(A:A,'ИЗ ОСНОВЫ НОМЕНКЛАТУР'!D:H,5,0) -> A | T30: =$R30*D30 -> 0 | U30: =$R30*E30 -> 0 | V30: =$R30*F30 -> 0 | W30: =$R30*G30 -> 0 | X30: =$R30*H30 -> 0 | Y30: =$R30*I30 -> 0 | Z30: =$R30*J30 -> 277957.35 | AA30: =$R30*K30 -> 127710.13 | ... AD30: =$R30*N30 -> 9381.0605 | AE30: =SUM(T30:AD30) -> 415048.54
A31: 19*0,4мм ПВХ Бодега AN | J31: 3800 | O31: 3800 | P31: =VLOOKUP(A31,'ИЗ ОСНОВЫ НОМЕНКЛАТУР'!D:E,2,0) -> Кромочные материалы | Q31: =VLOOKUP(A31,'ИЗ ОСНОВЫ НОМЕНКЛАТУР'!D:F,3,0) -> Кромка ПВХ Китай | R31: =VLOOKUP(A:A,'ИЗ ОСНОВЫ НОМЕНКЛАТУР'!D:G,4,0) -> 19 | S31: =VLOOKUP(A:A,'ИЗ ОСНОВЫ НОМЕНКЛАТУР'!D:H,5,0) -> C | T31: =$R31*D31 -> 0 | U31: =$R31*E31 -> 0 | V31: =$R31*F31 -> 0 | W31: =$R31*G31 -> 0 | X31: =$R31*H31 -> 0 | Y31: =$R31*I31 -> 0 | Z31: =$R31*J31 -> 72200 | AA31: =$R31*K31 -> 0 | ... AD31: =$R31*N31 -> 0 | AE31: =SUM(T31:AD31) -> 72200
A32: 19*0,4мм ПВХ Бодега белая AN | K32: 3600 | N32: 996 | O32: 4596 | P32: =VLOOKUP(A32,'ИЗ ОСНОВЫ НОМЕНКЛАТУР'!D:E,2,0) -> Кромочные материалы | Q32: =VLOOKUP(A32,'ИЗ ОСНОВЫ НОМЕНКЛАТУР'!D:F,3,0) -> Кромка ПВХ Китай | R32: =VLOOKUP(A:A,'ИЗ ОСНОВЫ НОМЕНКЛАТУР'!D:G,4,0) -> 18.18 | S32: =VLOOKUP(A:A,'ИЗ ОСНОВЫ НОМЕНКЛАТУР'!D:H,5,0) -> C | T32: =$R32*D32 -> 0 | U32: =$R32*E32 -> 0 | V32: =$R32*F32 -> 0 | W32: =$R32*G32 -> 0 | X32: =$R32*H32 -> 0 | Y32: =$R32*I32 -> 0 | Z32: =$R32*J32 -> 0 | AA32: =$R32*K32 -> 65448 | ... AD32: =$R32*N32 -> 18107.28 | AE32: =SUM(T32:AD32) -> 83555.28
A33: 19*0,4мм ПВХ Венге AN | I33: 81000 | K33: 1650 | N33: 4491 | O33: 87141 | P33: =VLOOKUP(A33,'ИЗ ОСНОВЫ НОМЕНКЛАТУР'!D:E,2,0) -> Кромочные материалы | Q33: =VLOOKUP(A33,'ИЗ ОСНОВЫ НОМЕНКЛАТУР'!D:F,3,0) -> Кромка ПВХ Китай | R33: =VLOOKUP(A:A,'ИЗ ОСНОВЫ НОМЕНКЛАТУР'!D:G,4,0) -> 17.215201 | S33: =VLOOKUP(A:A,'ИЗ ОСНОВЫ НОМЕНКЛАТУР'!D:H,5,0) -> C | T33: =$R33*D33 -> 0 | U33: =$R33*E33 -> 0 | V33: =$R33*F33 -> 0 | W33: =$R33*G33 -> 0 | X33: =$R33*H33 -> 0 | Y33: =$R33*I33 -> 1394431.3 | Z33: =$R33*J33 -> 0 | AA33: =$R33*K33 -> 28405.082 | ... AD33: =$R33*N33 -> 77313.468 | AE33: =SUM(T33:AD33) -> 1500149.8
A34: 19*0,4мм ПВХ Венге SD | I34: 10000 | O34: 10000 | P34: =VLOOKUP(A34,'ИЗ ОСНОВЫ НОМЕНКЛАТУР'!D:E,2,0) -> Кромочные материалы | Q34: =VLOOKUP(A34,'ИЗ ОСНОВЫ НОМЕНКЛАТУР'!D:F,3,0) -> Распродажа кромка | R34: =VLOOKUP(A:A,'ИЗ ОСНОВЫ НОМЕНКЛАТУР'!D:G,4,0) -> 12.575 | S34: =VLOOKUP(A:A,'ИЗ ОСНОВЫ НОМЕНКЛАТУР'!D:H,5,0) -> C | T34: =$R34*D34 -> 0 | U34: =$R34*E34 -> 0 | V34: =$R34*F34 -> 0 | W34: =$R34*G34 -> 0 | X34: =$R34*H34 -> 0 | Y34: =$R34*I34 -> 125750 | Z34: =$R34*J34 -> 0 | AA34: =$R34*K34 -> 0 | ... AD34: =$R34*N34 -> 0 | AE34: =SUM(T34:AD34) -> 125750
A35: 19*0,4мм ПВХ Выбеленное дерево AN | I35: 46000 | J35: 14180 | K35: 4000 | O35: 64180 | P35: =VLOOKUP(A35,'ИЗ ОСНОВЫ НОМЕНКЛАТУР'!D:E,2,0) -> Кромочные материалы | Q35: =VLOOKUP(A35,'ИЗ ОСНОВЫ НОМЕНКЛАТУР'!D:F,3,0) -> Кромка ПВХ Китай | R35: =VLOOKUP(A:A,'ИЗ ОСНОВЫ НОМЕНКЛАТУР'!D:G,4,0) -> 17.743178 | S35: =VLOOKUP(A:A,'ИЗ ОСНОВЫ НОМЕНКЛАТУР'!D:H,5,0) -> C | T35: =$R35*D35 -> 0 | U35: =$R35*E35 -> 0 | V35: =$R35*F35 -> 0 | W35: =$R35*G35 -> 0 | X35: =$R35*H35 -> 0 | Y35: =$R35*I35 -> 816186.2 | Z35: =$R35*J35 -> 251598.27 | AA35: =$R35*K35 -> 70972.713 | ... AD35: =$R35*N35 -> 0 | AE35: =SUM(T35:AD35) -> 1138757.2
A36: 19*0,4мм ПВХ Выбеленное дерево SD | I36: 60000 | O36: 60000 | P36: =VLOOKUP(A36,'ИЗ ОСНОВЫ НОМЕНКЛАТУР'!D:E,2,0) -> Кромочные материалы | Q36: =VLOOKUP(A36,'ИЗ ОСНОВЫ НОМЕНКЛАТУР'!D:F,3,0) -> Распродажа кромка | R36: =VLOOKUP(A:A,'ИЗ ОСНОВЫ НОМЕНКЛАТУР'!D:G,4,0) -> 12.56255 | S36: =VLOOKUP(A:A,'ИЗ ОСНОВЫ НОМЕНКЛАТУР'!D:H,5,0) -> C | T36: =$R36*D36 -> 0 | U36: =$R36*E36 -> 0 | V36: =$R36*F36 -> 0 | W36: =$R36*G36 -> 0 | X36: =$R36*H36 -> 0 | Y36: =$R36*I36 -> 753753 | Z36: =$R36*J36 -> 0 | AA36: =$R36*K36 -> 0 | ... AD36: =$R36*N36 -> 0 | AE36: =SUM(T36:AD36) -> 753753
A37: 19*0,4мм ПВХ Вяз AN | I37: 17000 | O37: 17000 | P37: =VLOOKUP(A37,'ИЗ ОСНОВЫ НОМЕНКЛАТУР'!D:E,2,0) -> Кромочные материалы | Q37: =VLOOKUP(A37,'ИЗ ОСНОВЫ НОМЕНКЛАТУР'!D:F,3,0) -> Кромка ПВХ Китай | R37: =VLOOKUP(A:A,'ИЗ ОСНОВЫ НОМЕНКЛАТУР'!D:G,4,0) -> 15.540294 | S37: =VLOOKUP(A:A,'ИЗ ОСНОВЫ НОМЕНКЛАТУР'!D:H,5,0) -> C | T37: =$R37*D37 -> 0 | U37: =$R37*E37 -> 0 | V37: =$R37*F37 -> 0 | W37: =$R37*G37 -> 0 | X37: =$R37*H37 -> 0 | Y37: =$R37*I37 -> 264185 | Z37: =$R37*J37 -> 0 | AA37: =$R37*K37 -> 0 | ... AD37: =$R37*N37 -> 0 | AE37: =SUM(T37:AD37) -> 264185
A38: 19*0,4мм ПВХ Дуб Вотан AN | I38: 42000 | J38: 8000 | K38: 3600 | O38: 53600 | P38: =VLOOKUP(A38,'ИЗ ОСНОВЫ НОМЕНКЛАТУР'!D:E,2,0) -> Кромочные материалы | Q38: =VLOOKUP(A38,'ИЗ ОСНОВЫ НОМЕНКЛАТУР'!D:F,3,0) -> Кромка ПВХ Китай | R38: =VLOOKUP(A:A,'ИЗ ОСНОВЫ НОМЕНКЛАТУР'!D:G,4,0) -> 18.106667 | S38: =VLOOKUP(A:A,'ИЗ ОСНОВЫ НОМЕНКЛАТУР'!D:H,5,0) -> C | T38: =$R38*D38 -> 0 | U38: =$R38*E38 -> 0 | V38: =$R38*F38 -> 0 | W38: =$R38*G38 -> 0 | X38: =$R38*H38 -> 0 | Y38: =$R38*I38 -> 760480 | Z38: =$R38*J38 -> 144853.33 | AA38: =$R38*K38 -> 65184 | ... AD38: =$R38*N38 -> 0 | AE38: =SUM(T38:AD38) -> 970517.33
A39: 19*0,4мм ПВХ Дуб млечный AN | I39: 32000 | K39: 5000 | O39: 37000 | P39: =VLOOKUP(A39,'ИЗ ОСНОВЫ НОМЕНКЛАТУР'!D:E,2,0) -> Кромочные материалы | Q39: =VLOOKUP(A39,'ИЗ ОСНОВЫ НОМЕНКЛАТУР'!D:F,3,0) -> Кромка ПВХ Китай | R39: =VLOOKUP(A:A,'ИЗ ОСНОВЫ НОМЕНКЛАТУР'!D:G,4,0) -> 16.26 | S39: =VLOOKUP(A:A,'ИЗ ОСНОВЫ НОМЕНКЛАТУР'!D:H,5,0) -> C | T39: =$R39*D39 -> 0 | U39: =$R39*E39 -> 0 | V39: =$R39*F39 -> 0 | W39: =$R39*G39 -> 0 | X39: =$R39*H39 -> 0 | Y39: =$R39*I39 -> 520320 | Z39: =$R39*J39 -> 0 | AA39: =$R39*K39 -> 81300 | ... AD39: =$R39*N39 -> 0 | AE39: =SUM(T39:AD39) -> 601620
A40: 19*0,4мм ПВХ Дуб сонома AN | I40: 64000 | J40: 10000 | K40: 1600 | N40: 700 | O40: 76300 | P40: =VLOOKUP(A40,'ИЗ ОСНОВЫ НОМЕНКЛАТУР'!D:E,2,0) -> Кромочные материалы | Q40: =VLOOKUP(A40,'ИЗ ОСНОВЫ НОМЕНКЛАТУР'!D:F,3,0) -> Кромка ПВХ Китай | R40: =VLOOKUP(A:A,'ИЗ ОСНОВЫ НОМЕНКЛАТУР'!D:G,4,0) -> 18.910628 | S40: =VLOOKUP(A:A,'ИЗ ОСНОВЫ НОМЕНКЛАТУР'!D:H,5,0) -> B | T40: =$R40*D40 -> 0 | U40: =$R40*E40 -> 0 | V40: =$R40*F40 -> 0 | W40: =$R40*G40 -> 0 | X40: =$R40*H40 -> 0 | Y40: =$R40*I40 -> 1210280.2 | Z40: =$R40*J40 -> 189106.28 | AA40: =$R40*K40 -> 30257.005 | ... AD40: =$R40*N40 -> 13237.44 | AE40: =SUM(T40:AD40) -> 1442880.9
A41: 19*0,4мм ПВХ Красный AN | I41: 12000 | J41: 3600 | K41: 3000 | O41: 18600 | P41: =VLOOKUP(A41,'ИЗ ОСНОВЫ НОМЕНКЛАТУР'!D:E,2,0) -> Кромочные материалы | Q41: =VLOOKUP(A41,'ИЗ ОСНОВЫ НОМЕНКЛАТУР'!D:F,3,0) -> Кромка ПВХ Китай | R41: =VLOOKUP(A:A,'ИЗ ОСНОВЫ НОМЕНКЛАТУР'!D:G,4,0) -> 12.6111 | S41: =VLOOKUP(A:A,'ИЗ ОСНОВЫ НОМЕНКЛАТУР'!D:H,5,0) -> C | T41: =$R41*D41 -> 0 | U41: =$R41*E41 -> 0 | V41: =$R41*F41 -> 0 | W41: =$R41*G41 -> 0 | X41: =$R41*H41 -> 0 | Y41: =$R41*I41 -> 151333.2 | Z41: =$R41*J41 -> 45399.96 | AA41: =$R41*K41 -> 37833.3 | ... AD41: =$R41*N41 -> 0 | AE41: =SUM(T41:AD41) -> 234566.46
...

Sheet ПРОДАЖИ
D1: qty | E1: qty | F1: qty | G1: qty | H1: qty | I1: qty | J1: qty | K1: qty | L1: amnt | M1: amnt | N1: amnt | O1: amnt | P1: amnt | Q1: amnt | R1: amnt | S1: amnt | T1: AMS ПО СЕБ.СТ. | U1: AMS ПО СЕБ.СТ. | V1: AMS ПО СЕБ.СТ. | W1: AMS ПО СЕБ.СТ. | X1: AMS ПО СЕБ.СТ. | Y1: AMS ПО СЕБ.СТ. | Z1: AMS ПО СЕБ.СТ. | AA1: AMS ПО СЕБ.СТ. | AB1: AMS ПО СЕБ.СТ.
A2: КАТЕГОРИЯ | B2: ПОДКАТЕГОРИЯ | C2: Номенклатура | D2: ТД Казыбаева ФУРНИТУРА магазин ( продажи 01.07.2024-01.07.2025 гг.) | E2: Казыбаева Склад Фурнитура TRADE ( продажи 01.07.2024-01.07.2025 гг.) | F2: Барыс Склад Фурнитура TRADE ( продажи 01.07.2024-01.07.2025 гг.) | G2: АО Склад Фурнитура TRADE ( продажи 01.07.2024-01.07.2025 гг.) | H2: Магазин фурнитуры ( продажи 01.07.2024-01.07.2025 гг.) | I2: склад фурнитура № 1 ( продажи 01.07.2024-01.07.2025 гг.) | J2: 6 Склад фурнитуры Овощная база Магазин ( продажи 01.07.2024-01.07.2025 гг.) | K2: 4 Склад фурнитуры АЗМ Шымкент Овощная база ( продажи 01.07.2024-01.07.2025 гг.) | L2: ТД Казыбаева ФУРНИТУРА магазин ( продажи 01.07.2024-01.07.2025 гг.) | M2: Казыбаева Склад Фурнитура TRADE ( продажи 01.07.2024-01.07.2025 гг.) | N2: Барыс Склад Фурнитура TRADE ( продажи 01.07.2024-01.07.2025 гг.) | O2: АО Склад Фурнитура TRADE ( продажи 01.07.2024-01.07.2025 гг.) | P2: Магазин фурнитуры ( продажи 01.07.2024-01.07.2025 гг.) | Q2: склад фурнитура № 1 ( продажи 01.07.2024-01.07.2025 гг.) | R2: 6 Склад фурнитуры Овощная база Магазин ( продажи 01.07.2024-01.07.2025 гг.) | S2: 4 Склад фурнитуры АЗМ Шымкент Овощная база ( продажи 01.07.2024-01.07.2025 гг.) | T2: ТД Казыбаева ФУРНИТУРА магазин ( продажи 01.07.2024-01.07.2025 гг.) | U2: Казыбаева Склад Фурнитура TRADE ( продажи 01.07.2024-01.07.2025 гг.) | V2: Барыс Склад Фурнитура TRADE ( продажи 01.07.2024-01.07.2025 гг.) | W2: АО Склад Фурнитура TRADE ( продажи 01.07.2024-01.07.2025 гг.) | X2: Магазин фурнитуры ( продажи 01.07.2024-01.07.2025 гг.) | Y2: склад фурнитура № 1 ( продажи 01.07.2024-01.07.2025 гг.) | Z2: 6 Склад фурнитуры Овощная база Магазин ( продажи 01.07.2024-01.07.2025 гг.) | AA2: 4 Склад фурнитуры АЗМ Шымкент Овощная база ( продажи 01.07.2024-01.07.2025 гг.) | AB2: тотал AMS | AC2: кат | AD2: кат-2 | AE2: abc
A3: Кромочные материалы | D3: 0 | E3: 0 | F3: 0 | G3: 0 | H3: 0 | I3: 0 | J3: 0 | K3: 0 | L3: 0 | M3: 0 | N3: 0 | O3: 0 | P3: 0 | Q3: 0 | R3: 0 | S3: 0 | T3: =L3/12 -> 0 | U3: =M3/12 -> 0 | V3: =N3/12 -> 0 | W3: =O3/12 -> 0 | X3: =P3/12 -> 0 | Y3: =Q3/12 -> 0 | Z3: =R3/12 -> 0 | AA3: =S3/12 -> 0 | AB3: =T3+U3+V3+W3+X3+Y3+Z3+AA3 -> 0 | AC3: =VLOOKUP(ПРОДАЖИ!C:C,'ИЗ ОСНОВЫ НОМЕНКЛАТУР'!D:E,2,0) -> #N/A | AD3: =VLOOKUP(C:C,'ИЗ ОСНОВЫ НОМЕНКЛАТУР'!D:F,3,0) -> #N/A | AE3: =VLOOKUP(C:C,'ИЗ ОСНОВЫ НОМЕНКЛАТУР'!D:H,5,0) -> #N/A
A4: Кромочные материалы | B4: Кромка ПВХ | D4: 0 | E4: 0 | F4: 0 | G4: 0 | H4: 0 | I4: 0 | J4: 0 | K4: 0 | L4: 0 | M4: 0 | N4: 0 | O4: 0 | P4: 0 | Q4: 0 | R4: 0 | S4: 0 | T4: =L4/12 -> 0 | U4: =M4/12 -> 0 | V4: =N4/12 -> 0 | W4: =O4/12 -> 0 | X4: =P4/12 -> 0 | Y4: =Q4/12 -> 0 | Z4: =R4/12 -> 0 | AA4: =S4/12 -> 0 | AB4: =T4+U4+V4+W4+X4+Y4+Z4+AA4 -> 0 | AC4: =VLOOKUP(ПРОДАЖИ!C:C,'ИЗ ОСНОВЫ НОМЕНКЛАТУР'!D:E,2,0) -> #N/A | AD4: =VLOOKUP(C:C,'ИЗ ОСНОВЫ НОМЕНКЛАТУР'!D:F,3,0) -> #N/A | AE4: =VLOOKUP(C:C,'ИЗ ОСНОВЫ НОМЕНКЛАТУР'!D:H,5,0) -> #N/A
A5: Кромочные материалы | B5: Кромка ПВХ Китай | D5: 0 | E5: 0 | F5: 0 | G5: 0 | H5: 0 | I5: 0 | J5: 0 | K5: 0 | L5: 0 | M5: 0 | N5: 0 | O5: 0 | P5: 0 | Q5: 0 | R5: 0 | S5: 0 | T5: =L5/12 -> 0 | U5: =M5/12 -> 0 | V5: =N5/12 -> 0 | W5: =O5/12 -> 0 | X5: =P5/12 -> 0 | Y5: =Q5/12 -> 0 | Z5: =R5/12 -> 0 | AA5: =S5/12 -> 0 | AB5: =T5+U5+V5+W5+X5+Y5+Z5+AA5 -> 0 | AC5: =VLOOKUP(ПРОДАЖИ!C:C,'ИЗ ОСНОВЫ НОМЕНКЛАТУР'!D:E,2,0) -> #N/A | AD5: =VLOOKUP(C:C,'ИЗ ОСНОВЫ НОМЕНКЛАТУР'!D:F,3,0) -> #N/A | AE5: =VLOOKUP(C:C,'ИЗ ОСНОВЫ НОМЕНКЛАТУР'!D:H,5,0) -> #N/A
A6: Кромочные материалы | B6: 19*0,8мм ПВХ | D6: 0 | E6: 0 | F6: 0 | G6: 0 | H6: 0 | I6: 0 | J6: 0 | K6: 0 | L6: 0 | M6: 0 | N6: 0 | O6: 0 | P6: 0 | Q6: 0 | R6: 0 | S6: 0 | T6: =L6/12 -> 0 | U6: =M6/12 -> 0 | V6: =N6/12 -> 0 | W6: =O6/12 -> 0 | X6: =P6/12 -> 0 | Y6: =Q6/12 -> 0 | Z6: =R6/12 -> 0 | AA6: =S6/12 -> 0 | AB6: =T6+U6+V6+W6+X6+Y6+Z6+AA6 -> 0 | AC6: =VLOOKUP(ПРОДАЖИ!C:C,'ИЗ ОСНОВЫ НОМЕНКЛАТУР'!D:E,2,0) -> #N/A | AD6: =VLOOKUP(C:C,'ИЗ ОСНОВЫ НОМЕНКЛАТУР'!D:F,3,0) -> #N/A | AE6: =VLOOKUP(C:C,'ИЗ ОСНОВЫ НОМЕНКЛАТУР'!D:H,5,0) -> #N/A
A7: Кромочные материалы | C7: 19*0,8мм ПВХ Белый AN | D7: 1397761 | E7: 520079 | F7: 1709519 | G7: 117814 | H7: 738367 | I7: 1546280 | J7: 1800 | K7: 1782465 | L7: 27977554 | M7: 9629845.9 | N7: 31636898 | O7: 2189874.1 | P7: 13645556 | Q7: 27971742 | R7: 29186 | S7: 28053748 | T7: =L7/12 -> 2331462.8 | U7: =M7/12 -> 802487.16 | V7: =N7/12 -> 2636408.2 | W7: =O7/12 -> 182489.51 | X7: =P7/12 -> 1137129.7 | Y7: =Q7/12 -> 2330978.5 | Z7: =R7/12 -> 2432.1667 | AA7: =S7/12 -> 2337812.3 | AB7: =T7+U7+V7+W7+X7+Y7+Z7+AA7 -> 11761200 | AC7: =VLOOKUP(ПРОДАЖИ!C:C,'ИЗ ОСНОВЫ НОМЕНКЛАТУР'!D:E,2,0) -> Кромочные материалы | AD7: =VLOOKUP(C:C,'ИЗ ОСНОВЫ НОМЕНКЛАТУР'!D:F,3,0) -> Кромка ПВХ Китай | AE7: =VLOOKUP(C:C,'ИЗ ОСНОВЫ НОМЕНКЛАТУР'!D:H,5,0) -> A
A8: Кромочные материалы | C8: 19*0,8мм ПВХ Дуб сонома AN | D8: 168499 | E8: 77200 | F8: 132474 | G8: 10134 | H8: 129885 | I8: 208513 | J8: 1600 | K8: 58766 | L8: 4184268.9 | M8: 1939265.1 | N8: 3247768 | O8: 264045.7 | P8: 3315092.6 | Q8: 5264210.6 | R8: 38750.81 | S8: 1452541.6 | T8: =L8/12 -> 348689.07 | U8: =M8/12 -> 161605.42 | V8: =N8/12 -> 270647.34 | W8: =O8/12 -> 22003.808 | X8: =P8/12 -> 276257.71 | Y8: =Q8/12 -> 438684.22 | Z8: =R8/12 -> 3229.2342 | AA8: =S8/12 -> 121045.13 | AB8: =T8+U8+V8+W8+X8+Y8+Z8+AA8 -> 1642161.9 | AC8: =VLOOKUP(ПРОДАЖИ!C:C,'ИЗ ОСНОВЫ НОМЕНКЛАТУР'!D:E,2,0) -> Кромочные материалы | AD8: =VLOOKUP(C:C,'ИЗ ОСНОВЫ НОМЕНКЛАТУР'!D:F,3,0) -> Кромка ПВХ Китай | AE8: =VLOOKUP(C:C,'ИЗ ОСНОВЫ НОМЕНКЛАТУР'!D:H,5,0) -> A
A9: Кромочные материалы | C9: 19*0,8мм ПВХ Дуб Вотан AN | D9: 176065 | E9: 18200 | F9: 180289 | G9: 22501 | H9: 166449 | I9: 99000 | J9: 800 | K9: 117622 | L9: 5120115.9 | M9: 530730.86 | N9: 4451845.3 | O9: 561167.57 | P9: 4249831.3 | Q9: 2532691.8 | R9: 20076.04 | S9: 2951405.9 | T9: =L9/12 -> 426676.33 | U9: =M9/12 -> 44227.572 | V9: =N9/12 -> 370987.1 | W9: =O9/12 -> 46763.964 | X9: =P9/12 -> 354152.61 | Y9: =Q9/12 -> 211057.65 | Z9: =R9/12 -> 1673.0033 | AA9: =S9/12 -> 245950.49 | AB9: =T9+U9+V9+W9+X9+Y9+Z9+AA9 -> 1701488.7 | AC9: =VLOOKUP(ПРОДАЖИ!C:C,'ИЗ ОСНОВЫ НОМЕНКЛАТУР'!D:E,2,0) -> Кромочные материалы | AD9: =VLOOKUP(C:C,'ИЗ ОСНОВЫ НОМЕНКЛАТУР'!D:F,3,0) -> Кромка ПВХ Китай | AE9: =VLOOKUP(C:C,'ИЗ ОСНОВЫ НОМЕНКЛАТУР'!D:H,5,0) -> A
A10: Кромочные материалы | C10: 19*0,8мм ПВХ Серый SJ | D10: 122753 | E10: 24800 | F10: 98781 | G10: 12107 | H10: 104677 | I10: 66700 | J10: 400 | K10: 127152 | L10: 2217369.3 | M10: 452489.3 | N10: 1783910.9 | O10: 222545.7 | P10: 1913177.5 | Q10: 1208221.9 | R10: 7073.17 | S10: 2322400.6 | T10: =L10/12 -> 184780.77 | U10: =M10/12 -> 37707.442 | V10: =N10/12 -> 148659.24 | W10: =O10/12 -> 18545.475 | X10: =P10/12 -> 159431.46 | Y10: =Q10/12 -> 100685.16 | Z10: =R10/12 -> 589.43083 | AA10: =S10/12 -> 193533.38 | AB10: =T10+U10+V10+W10+X10+Y10+Z10+AA10 -> 843932.36 | AC10: =VLOOKUP(ПРОДАЖИ!C:C,'ИЗ ОСНОВЫ НОМЕНКЛАТУР'!D:E,2,0) -> Кромочные материалы | AD10: =VLOOKUP(C:C,'ИЗ ОСНОВЫ НОМЕНКЛАТУР'!D:F,3,0) -> Кромка ПВХ Китай | AE10: =VLOOKUP(C:C,'ИЗ ОСНОВЫ НОМЕНКЛАТУР'!D:H,5,0) -> A
A11: Кромочные материалы | C11: 19*0,8мм ПВХ Тэффи SJ | D11: 60185 | E11: 2000 | F11: 50983 | G11: 6000 | H11: 111813 | I11: 72900 | J11: 600 | K11: 61169 | L11: 1059256 | M11: 35200 | N11: 898551.38 | O11: 106500 | P11: 1993577.2 | Q11: 1297907.9 | R11: 10679.37 | S11: 1091571.7 | T11: =L11/12 -> 88271.333 | U11: =M11/12 -> 2933.3333 | V11: =N11/12 -> 74879.282 | W11: =O11/12 -> 8875 | X11: =P11/12 -> 166131.43 | Y11: =Q11/12 -> 108158.99 | Z11: =R11/12 -> 889.9475 | AA11: =S11/12 -> 90964.308 | AB11: =T11+U11+V11+W11+X11+Y11+Z11+AA11 -> 541103.63 | AC11: =VLOOKUP(ПРОДАЖИ!C:C,'ИЗ ОСНОВЫ НОМЕНКЛАТУР'!D:E,2,0) -> Кромочные материалы | AD11: =VLOOKUP(C:C,'ИЗ ОСНОВЫ НОМЕНКЛАТУР'!D:F,3,0) -> Кромка ПВХ Китай | AE11: =VLOOKUP(C:C,'ИЗ ОСНОВЫ НОМЕНКЛАТУР'!D:H,5,0) -> A
A12: Кромочные материалы | C12: 19*0,8мм ПВХ Тэффи AN | D12: 103898 | E12: 9020 | F12: 50331 | G12: 8260 | H12: 66838 | I12: 42400 | J12: 600 | K12: 96259 | L12: 1957051.9 | M12: 160613.16 | N12: 960658.82 | O12: 155643.99 | P12: 1906615.7 | Q12: 1278182.9 | R12: 10680 | S12: 1724703.3 | T12: =L12/12 -> 163087.66 | U12: =M12/12 -> 13384.43 | V12: =N12/12 -> 80054.902 | W12: =O12/12 -> 12970.332 | X12: =P12/12 -> 158884.64 | Y12: =Q12/12 -> 106515.24 | Z12: =R12/12 -> 890 | AA12: =S12/12 -> 143725.27 | AB12: =T12+U12+V12+W12+X12+Y12+Z12+AA12 -> 679512.48 | AC12: =VLOOKUP(ПРОДАЖИ!C:C,'ИЗ ОСНОВЫ НОМЕНКЛАТУР'!D:E,2,0) -> Кромочные материалы | AD12: =VLOOKUP(C:C,'ИЗ ОСНОВЫ НОМЕНКЛАТУР'!D:F,3,0) -> Кромка ПВХ Китай | AE12: =VLOOKUP(C:C,'ИЗ ОСНОВЫ НОМЕНКЛАТУР'!D:H,5,0) -> A
A13: Кромочные материалы | C13: 19*0,8мм ПВХ Черный AN | D13: 153308 | E13: 37858 | F13: 97984 | G13: 5878 | H13: 32055 | I13: 39710 | J13: 400 | K13: 70396 | L13: 2902112.4 | M13: 681709.41 | N13: 1919044 | O13: 109641.97 | P13: 592327.77 | Q13: 742134.46 | R13: 9726.91 | S13: 1276862.4 | T13: =L13/12 -> 241842.7 | U13: =M13/12 -> 56809.118 | V13: =N13/12 -> 159920.33 | W13: =O13/12 -> 9136.8308 | X13: =P13/12 -> 49360.647 | Y13: =Q13/12 -> 61844.538 | Z13: =R13/12 -> 810.57583 | AA13: =S13/12 -> 106405.2 | AB13: =T13+U13+V13+W13+X13+Y13+Z13+AA13 -> 686129.94 | AC13: =VLOOKUP(ПРОДАЖИ!C:C,'ИЗ ОСНОВЫ НОМЕНКЛАТУР'!D:E,2,0) -> Кромочные материалы | AD13: =VLOOKUP(C:C,'ИЗ ОСНОВЫ НОМЕНКЛАТУР'!D:F,3,0) -> Кромка ПВХ Китай | AE13: =VLOOKUP(C:C,'ИЗ ОСНОВЫ НОМЕНКЛАТУР'!D:H,5,0) -> A
A14: Кромочные материалы | C14: 19*0,8мм ПВХ Белый (Гладкий) AN | D14: 343849 | E14: 23000 | F14: 136196 | G14: 29502 | H14: 49162 | I14: 42240 | J14: 803 | K14: 159220 | L14: 7785864.4 | M14: 510245.27 | N14: 3164468.7 | O14: 641148.8 | P14: 1089334.8 | Q14: 957704.07 | R14: 15979.7 | S14: 3280901.8 | T14: =L14/12 -> 648822.03 | U14: =M14/12 -> 42520.439 | V14: =N14/12 -> 263705.72 | W14: =O14/12 -> 53429.067 | X14: =P14/12 -> 90777.9 | Y14: =Q14/12 -> 79808.673 | Z14: =R14/12 -> 1331.6417 | AA14: =S14/12 -> 273408.49 | AB14: =T14+U14+V14+W14+X14+Y14+Z14+AA14 -> 1453804 | AC14: =VLOOKUP(ПРОДАЖИ!C:C,'ИЗ ОСНОВЫ НОМЕНКЛАТУР'!D:E,2,0) -> Кромочные материалы | AD14: =VLOOKUP(C:C,'ИЗ ОСНОВЫ НОМЕНКЛАТУР'!D:F,3,0) -> Кромка ПВХ Китай | AE14: =VLOOKUP(C:C,'ИЗ ОСНОВЫ НОМЕНКЛАТУР'!D:H,5,0) -> A
A15: Кромочные материалы | C15: 19*0,8мм ПВХ Вулканический серый AN | D15: 81600 | E15: 3000 | F15: 31118 | G15: 6151 | H15: 29450 | I15: 12210 | J15: 800 | K15: 59867 | L15: 1891308.8 | M15: 69329.63 | N15: 718946.34 | O15: 142001.08 | P15: 680434.8 | Q15: 282135.48 | R15: 18449.19 | S15: 1378481.5 | T15: =L15/12 -> 157609.07 | U15: =M15/12 -> 5777.4692 | V15: =N15/12 -> 59912.195 | W15: =O15/12 -> 11833.423 | X15: =P15/12 -> 56702.9 | Y15: =Q15/12 -> 23511.29 | Z15: =R15/12 -> 1537.4325 | AA15: =S15/12 -> 114873.46 | AB15: =T15+U15+V15+W15+X15+Y15+Z15+AA15 -> 431757.24 | AC15: =VLOOKUP(ПРОДАЖИ!C:C,'ИЗ ОСНОВЫ НОМЕНКЛАТУР'!D:E,2,0) -> Кромочные материалы | AD15: =VLOOKUP(C:C,'ИЗ ОСНОВЫ НОМЕНКЛАТУР'!D:F,3,0) -> Кромка ПВХ Китай | AE15: =VLOOKUP(C:C,'ИЗ ОСНОВЫ НОМЕНКЛАТУР'!D:H,5,0) -> A
A16: Кромочные материалы | C16: 19*0,8мм ПВХ Антрацит AN | D16: 118711 | E16: 8700 | F16: 50202 | G16: 3932 | H16: 29463 | I16: 19430 | J16: 1000 | K16: 115269 | L16: 2396709.4 | M16: 173941.18 | N16: 1039548.6 | O16: 80475.7 | P16: 591737.27 | Q16: 393747.56 | R16: 19482.88 | S16: 2168650.9 | T16: =L16/12 -> 199725.79 | U16: =M16/12 -> 14495.098 | V16: =N16/12 -> 86629.048 | W16: =O16/12 -> 6706.3083 | X16: =P16/12 -> 49311.439 | Y16: =Q16/12 -> 32812.297 | Z16: =R16/12 -> 1623.5733 | AA16: =S16/12 -> 180720.91 | AB16: =T16+U16+V16+W16+X16+Y16+Z16+AA16 -> 572024.46 | AC16: =VLOOKUP(ПРОДАЖИ!C:C,'ИЗ ОСНОВЫ НОМЕНКЛАТУР'!D:E,2,0) -> Кромочные материалы | AD16: =VLOOKUP(C:C,'ИЗ ОСНОВЫ НОМЕНКЛАТУР'!D:F,3,0) -> Кромка ПВХ Китай | AE16: =VLOOKUP(C:C,'ИЗ ОСНОВЫ НОМЕНКЛАТУР'!D:H,5,0) -> A
A17: Кромочные материалы | C17: 19*0,8мм ПВХ Ясень шимо светлый AN | D17: 72133 | E17: 58800 | F17: 25854 | G17: 2165 | H17: 22287 | I17: 14700 | J17: 200 | K17: 5849 | L17: 1851227.9 | M17: 1414097.4 | N17: 668558.86 | O17: 55150.49 | P17: 542383.41 | Q17: 369403.04 | R17: 5716.37 | S17: 151929.71 | T17: =L17/12 -> 154268.99 | U17: =M17/12 -> 117841.45 | V17: =N17/12 -> 55713.238 | W17: =O17/12 -> 4595.8742 | X17: =P17/12 -> 45198.618 | Y17: =Q17/12 -> 30783.587 | Z17: =R17/12 -> 476.36417 | AA17: =S17/12 -> 12660.809 | AB17: =T17+U17+V17+W17+X17+Y17+Z17+AA17 -> 421538.93 | AC17: =VLOOKUP(ПРОДАЖИ!C:C,'ИЗ ОСНОВЫ НОМЕНКЛАТУР'!D:E,2,0) -> Кромочные материалы | AD17: =VLOOKUP(C:C,'ИЗ ОСНОВЫ НОМЕНКЛАТУР'!D:F,3,0) -> Кромка ПВХ Китай | AE17: =VLOOKUP(C:C,'ИЗ ОСНОВЫ НОМЕНКЛАТУР'!D:H,5,0) -> A
A18: Кромочные материалы | C18: 19*0,8мм ПВХ Серый AN | D18: 99580 | E18: 3816 | F18: 42073 | G18: 6897 | H18: 51073 | I18: 37950 | J18: 200 | K18: 44879 | L18: 2043489.7 | M18: 78275.53 | N18: 863957.02 | O18: 141437.56 | P18: 1051446 | Q18: 781007.89 | R18: 4688.14 | S18: 926500.81 | T18: =L18/12 -> 170290.81 | U18: =M18/12 -> 6522.9608 | V18: =N18/12 -> 71996.418 | W18: =O18/12 -> 11786.463 | X18: =P18/12 -> 87620.502 | Y18: =Q18/12 -> 65083.991 | Z18: =R18/12 -> 390.67833 | AA18: =S18/12 -> 77208.401 | AB18: =T18+U18+V18+W18+X18+Y18+Z18+AA18 -> 490900.22 | AC18: =VLOOKUP(ПРОДАЖИ!C:C,'ИЗ ОСНОВЫ НОМЕНКЛАТУР'!D:E,2,0) -> Кромочные материалы | AD18: =VLOOKUP(C:C,'ИЗ ОСНОВЫ НОМЕНКЛАТУР'!D:F,3,0) -> Кромка ПВХ Китай | AE18: =VLOOKUP(C:C,'ИЗ ОСНОВЫ НОМЕНКЛАТУР'!D:H,5,0) -> A
... A213: Кромочные материалы | C213: 19*0,8мм ПВХ Ена AN | D213: 557 | E213: 0 | F213: 500 | G213: 0 | H213: 934 | I213: 400 | J213: 200 | K213: 2664 | L213: 20218.59 | M213: 0 | N213: 118617.59 | O213: 0 | P213: 103667.62 | Q213: 44397.27 | R213: 6209.73 | S213: 82713.6 | T213: =L213/12 -> 1684.8825 | U213: =M213/12 -> 0 | V213: =N213/12 -> 9884.7992 | W213: =O213/12 -> 0 | X213: =P213/12 -> 8638.9683 | Y213: =Q213/12 -> 3699.7725 | Z213: =R213/12 -> 517.4775 | AA213: =S213/12 -> 6892.8 | AB213: =T213+U213+V213+W213+X213+Y213+Z213+AA213 -> 31318.7 | AC213: =VLOOKUP(ПРОДАЖИ!C:C,'ИЗ ОСНОВЫ НОМЕНКЛАТУР'!D:E,2,0) -> Кромочные материалы | AD213: =VLOOKUP(C:C,'ИЗ ОСНОВЫ НОМЕНКЛАТУР'!D:F,3,0) -> Кромка ПВХ Китай | AE213: =VLOOKUP(C:C,'ИЗ ОСНОВЫ НОМЕНКЛАТУР'!D:H,5,0) -> C
A214: Кромочные материалы | B214: 19*1,5мм ПВХ | D214: 0 | E214: 0 | F214: 0 | G214: 0 | H214: 0 | I214: 0 | J214: 0 | K214: 0 | L214: 0 | M214: 0 | N214: 0 | O214: 0 | P214: 0 | Q214: 0 | R214: 0 | S214: 0 | T214: =L214/12 -> 0 | U214: =M214/12 -> 0 | V214: =N214/12 -> 0 | W214: =O214/12 -> 0 | X214: =P214/12 -> 0 | Y214: =Q214/12 -> 0 | Z214: =R214/12 -> 0 | AA214: =S214/12 -> 0 | AB214: =T214+U214+V214+W214+X214+Y214+Z214+AA214 -> 0 | AC214: =VLOOKUP(ПРОДАЖИ!C:C,'ИЗ ОСНОВЫ НОМЕНКЛАТУР'!D:E,2,0) -> #N/A | AD214: =VLOOKUP(C:C,'ИЗ ОСНОВЫ НОМЕНКЛАТУР'!D:F,3,0) -> #N/A | AE214: =VLOOKUP(C:C,'ИЗ ОСНОВЫ НОМЕНКЛАТУР'!D:H,5,0) -> #N/A
A215: Кромочные материалы | C215: 19*1,5мм ПВХ Белый AN | D215: 92876 | E215: 216670 | F215: 43902 | G215: 7935 | H215: 776 | I215: 96900 | J215: 0 | K215: 2070 | L215: 3472191.9 | M215: 8042869.5 | N215: 1782025.8 | O215: 300449.61 | P215: 28798.23 | Q215: 3580918.8 | R215: 0 | S215: 76024.76 | T215: =L215/12 -> 289349.33 | U215: =M215/12 -> 670239.12 | V215: =N215/12 -> 148502.15 | W215: =O215/12 -> 25037.467 | X215: =P215/12 -> 2399.8525 | Y215: =Q215/12 -> 298409.9 | Z215: =R215/12 -> 0 | AA215: =S215/12 -> 6335.3967 | AB215: =T215+U215+V215+W215+X215+Y215+Z215+AA215 -> 1440273.2 | AC215: =VLOOKUP(ПРОДАЖИ!C:C,'ИЗ ОСНОВЫ НОМЕНКЛАТУР'!D:E,2,0) -> Кромочные материалы | AD215: =VLOOKUP(C:C,'ИЗ ОСНОВЫ НОМЕНКЛАТУР'!D:F,3,0) -> Кромка ПВХ Китай | AE215: =VLOOKUP(C:C,'ИЗ ОСНОВЫ НОМЕНКЛАТУР'!D:H,5,0) -> A
A216: Кромочные материалы | C216: 19*1,5мм ПВХ Ясень шимо светлый SJ | D216: 1400 | E216: 93900 | F216: 3439 | G216: 0 | H216: 0 | I216: 46600 | J216: 0 | K216: 0 | L216: 52466.58 | M216: 3439415.4 | N216: 135496.6 | O216: 0 | P216: 0 | Q216: 1767240 | R216: 0 | S216: 0 | T216: =L216/12 -> 4372.215 | U216: =M216/12 -> 286617.95 | V216: =N216/12 -> 11291.383 | W216: =O216/12 -> 0 | X216: =P216/12 -> 0 | Y216: =Q216/12 -> 147270 | Z216: =R216/12 -> 0 | AA216: =S216/12 -> 0 | AB216: =T216+U216+V216+W216+X216+Y216+Z216+AA216 -> 449551.55 | AC216: =VLOOKUP(ПРОДАЖИ!C:C,'ИЗ ОСНОВЫ НОМЕНКЛАТУР'!D:E,2,0) -> Кромочные материалы | AD216: =VLOOKUP(C:C,'ИЗ ОСНОВЫ НОМЕНКЛАТУР'!D:F,3,0) -> Кромка ПВХ Китай | AE216: =VLOOKUP(C:C,'ИЗ ОСНОВЫ НОМЕНКЛАТУР'!D:H,5,0) -> A
A217: Кромочные материалы | C217: 19*1,5мм ПВХ Дуб вотан AN | D217: 24496 | E217: 89080 | F217: 7246 | G217: 1502 | H217: 171 | I217: 12100 | J217: 0 | K217: 0 | L217: 1045210.1 | M217: 3790321.6 | N217: 311045.67 | O217: 71747.68 | P217: 7852.28 | Q217: 526137.99 | R217: 0 | S217: 0 | T217: =L217/12 -> 87100.844 | U217: =M217/12 -> 315860.14 | V217: =N217/12 -> 25920.472 | W217: =O217/12 -> 5978.9733 | X217: =P217/12 -> 654.35667 | Y217: =Q217/12 -> 43844.832 | Z217: =R217/12 -> 0 | AA217: =S217/12 -> 0 | AB217: =T217+U217+V217+W217+X217+Y217+Z217+AA217 -> 479359.62 | AC217: =VLOOKUP(ПРОДАЖИ!C:C,'ИЗ ОСНОВЫ НОМЕНКЛАТУР'!D:E,2,0) -> Кромочные материалы | AD217: =VLOOKUP(C:C,'ИЗ ОСНОВЫ НОМЕНКЛАТУР'!D:F,3,0) -> Кромка ПВХ Китай | AE217: =VLOOKUP(C:C,'ИЗ ОСНОВЫ НОМЕНКЛАТУР'!D:H,5,0) -> A
A218: Кромочные материалы | C218: 19*1,5мм ПВХ Ясень шимо светлый AN | D218: 8486 | E218: 79000 | F218: 4756 | G218: 198 | H218: 930 | I218: 47700 | J218: 0 | K218: 1291 | L218: 383187.6 | M218: 3450486.7 | N218: 214564.8 | O218: 7665.68 | P218: 41847.24 | Q218: 2086116.4 | R218: 0 | S218: 58388.86 | T218: =L218/12 -> 31932.3 | U218: =M218/12 -> 287540.55 | V218: =N218/12 -> 17880.4 | W218: =O218/12 -> 638.80667 | X218: =P218/12 -> 3487.27 | Y218: =Q218/12 -> 173843.04 | Z218: =R218/12 -> 0 | AA218: =S218/12 -> 4865.7383 | AB218: =T218+U218+V218+W218+X218+Y218+Z218+AA218 -> 520188.11 | AC218: =VLOOKUP(ПРОДАЖИ!C:C,'ИЗ ОСНОВЫ НОМЕНКЛАТУР'!D:E,2,0) -> Кромочные материалы | AD218: =VLOOKUP(C:C,'ИЗ ОСНОВЫ НОМЕНКЛАТУР'!D:F,3,0) -> Кромка ПВХ Китай | AE218: =VLOOKUP(C:C,'ИЗ ОСНОВЫ НОМЕНКЛАТУР'!D:H,5,0) -> A
A219: Кромочные материалы | C219: 19*1,5мм ПВХ Бежевый AN | D219: 63522 | E219: 71800 | F219: 100 | G219: 1000 | H219: 110 | I219: 1000 | J219: 0 | K219: 0 | L219: 2807622.9 | M219: 3177692 | N219: 4571.83 | O219: 44030 | P219: 5391.1 | Q219: 49010 | R219: 0 | S219: 0 | T219: =L219/12 -> 233968.57 | U219: =M219/12 -> 264807.67 | V219: =N219/12 -> 380.98583 | W219: =O219/12 -> 3669.1667 | X219: =P219/12 -> 449.25833 | Y219: =Q219/12 -> 4084.1667 | Z219: =R219/12 -> 0 | AA219: =S219/12 -> 0 | AB219: =T219+U219+V219+W219+X219+Y219+Z219+AA219 -> 507359.81 | AC219: =VLOOKUP(ПРОДАЖИ!C:C,'ИЗ ОСНОВЫ НОМЕНКЛАТУР'!D:E,2,0) -> Кромочные материалы | AD219: =VLOOKUP(C:C,'ИЗ ОСНОВЫ НОМЕНКЛАТУР'!D:F,3,0) -> Кромка ПВХ Китай | AE219: =VLOOKUP(C:C,'ИЗ ОСНОВЫ НОМЕНКЛАТУР'!D:H,5,0) -> A
A220: Кромочные материалы | C220: 19*1,5мм ПВХ Ясень шимо темный AN | D220: 25847 | E220: 70200 | F220: 3231 | G220: 0 | H220: 7 | I220: 35500 | J220: 0 | K220: 0 | L220: 1252753.8 | M220: 3369202 | N220: 166925.49 | O220: 0 | P220: 338.16 | Q220: 1692752.5 | R220: 0 | S220: 0 | T220: =L220/12 -> 104396.15 | U220: =M220/12 -> 280766.84 | V220: =N220/12 -> 13910.457 | W220: =O220/12 -> 0 | X220: =P220/12 -> 28.18 | Y220: =Q220/12 -> 141062.71 | Z220: =R220/12 -> 0 | AA220: =S220/12 -> 0 | AB220: =T220+U220+V220+W220+X220+Y220+Z220+AA220 -> 540164.33 | AC220: =VLOOKUP(ПРОДАЖИ!C:C,'ИЗ ОСНОВЫ НОМЕНКЛАТУР'!D:E,2,0) -> Кромочные материалы | AD220: =VLOOKUP(C:C,'ИЗ ОСНОВЫ НОМЕНКЛАТУР'!D:F,3,0) -> Кромка ПВХ Китай | AE220: =VLOOKUP(C:C,'ИЗ ОСНОВЫ НОМЕНКЛАТУР'!D:H,5,0) -> A
A221: Кромочные материалы | C221: 19*1,5мм ПВХ Дуб Сонома AN | D221: 17817 | E221: 23498 | F221: 10513 | G221: 100 | H221: 262 | I221: 16800 | J221: 0 | K221: 408 | L221: 858235.42 | M221: 1138312 | N221: 478922.07 | O221: 6048.42 | P221: 11077.59 | Q221: 714698.64 | R221: 0 | S221: 19476.46 | T221: =L221/12 -> 71519.618 | U221: =M221/12 -> 94859.333 | V221: =N221/12 -> 39910.173 | W221: =O221/12 -> 504.035 | X221: =P221/12 -> 923.1325 | Y221: =Q221/12 -> 59558.22 | Z221: =R221/12 -> 0 | AA221: =S221/12 -> 1623.0383 | AB221: =T221+U221+V221+W221+X221+Y221+Z221+AA221 -> 268897.55 | AC221: =VLOOKUP(ПРОДАЖИ!C:C,'ИЗ ОСНОВЫ НОМЕНКЛАТУР'!D:E,2,0) -> Кромочные материалы | AD221: =VLOOKUP(C:C,'ИЗ ОСНОВЫ НОМЕНКЛАТУР'!D:F,3,0) -> Кромка ПВХ Китай | AE221: =VLOOKUP(C:C,'ИЗ ОСНОВЫ НОМЕНКЛАТУР'!D:H,5,0) -> A
A222: Кромочные материалы | C222: 19*1,5мм ПВХ Ясень шимо темный SJ | D222: 109 | E222: 33500 | F222: 0 | G222: 0 | H222: 0 | I222: 22500 | J222: 0 | K222: 0 | L222: 4687 | M222: 1430475 | N222: 0 | O222: 0 | P222: 0 | Q222: 956100 | R222: 0 | S222: 0 | T222: =L222/12 -> 390.58333 | U222: =M222/12 -> 119206.25 | V222: =N222/12 -> 0 | W222: =O222/12 -> 0 | X222: =P222/12 -> 0 | Y222: =Q222/12 -> 79675 | Z222: =R222/12 -> 0 | AA222: =S222/12 -> 0 | AB222: =T222+U222+V222+W222+X222+Y222+Z222+AA222 -> 199271.83 | AC222: =VLOOKUP(ПРОДАЖИ!C:C,'ИЗ ОСНОВЫ НОМЕНКЛАТУР'!D:E,2,0) -> Кромочные материалы | AD222: =VLOOKUP(C:C,'ИЗ ОСНОВЫ НОМЕНКЛАТУР'!D:F,3,0) -> Кромка ПВХ Китай | AE222: =VLOOKUP(C:C,'ИЗ ОСНОВЫ НОМЕНКЛАТУР'!D:H,5,0) -> A
A223: Кромочные материалы | C223: 19*1,5мм ПВХ Серый AN | D223: 20672 | E223: 25400 | F223: 3777 | G223: 627 | H223: 750 | I223: 4800 | J223: 300 | K223: 574 | L223: 775710.74 | M223: 951131.91 | N223: 176157.17 | O223: 28549.04 | P223: 32702.42 | Q223: 212563.58 | R223: 12487.13 | S223: 22245.17 | T223: =L223/12 -> 64642.562 | U223: =M223/12 -> 79260.993 | V223: =N223/12 -> 14679.764 | W223: =O223/12 -> 2379.0867 | X223: =P223/12 -> 2725.2017 | Y223: =Q223/12 -> 17713.632 | Z223: =R223/12 -> 1040.5942 | AA223: =S223/12 -> 1853.7642 | AB223: =T223+U223+V223+W223+X223+Y223+Z223+AA223 -> 184295.6 | AC223: =VLOOKUP(ПРОДАЖИ!C:C,'ИЗ ОСНОВЫ НОМЕНКЛАТУР'!D:E,2,0) -> Кромочные материалы | AD223: =VLOOKUP(C:C,'ИЗ ОСНОВЫ НОМЕНКЛАТУР'!D:F,3,0) -> Кромка ПВХ Китай | AE223: =VLOOKUP(C:C,'ИЗ ОСНОВЫ НОМЕНКЛАТУР'!D:H,5,0) -> A
A224: Кромочные материалы | C224: 19*1,5мм ПВХ Дуб сонома SJ | D224: 3839 | E224: 11500 | F224: 58 | G224: 100 | H224: 158 | I224: 27700 | J224: 0 | K224: 0 | L224: 161809.12 | M224: 475018.85 | N224: 2331.12 | O224: 4300 | P224: 6794 | Q224: 1160635.6 | R224: 0 | S224: 0 | T224: =L224/12 -> 13484.093 | U224: =M224/12 -> 39584.904 | V224: =N224/12 -> 194.26 | W224: =O224/12 -> 358.33333 | X224: =P224/12 -> 566.16667 | Y224: =Q224/12 -> 96719.637 | Z224: =R224/12 -> 0 | AA224: =S224/12 -> 0 | AB224: =T224+U224+V224+W224+X224+Y224+Z224+AA224 -> 150907.39 | AC224: =VLOOKUP(ПРОДАЖИ!C:C,'ИЗ ОСНОВЫ НОМЕНКЛАТУР'!D:E,2,0) -> Кромочные материалы | AD224: =VLOOKUP(C:C,'ИЗ ОСНОВЫ НОМЕНКЛАТУР'!D:F,3,0) -> Кромка ПВХ Китай | AE224: =VLOOKUP(C:C,'ИЗ ОСНОВЫ НОМЕНКЛАТУР'!D:H,5,0) -> A
A225: Кромочные материалы | C225: 19*1,5мм ПВХ Антрацит AN | D225: 5979 | E225: 35000 | F225: 833 | G225: 0 | H225: 136 | I225: 2300 | J225: 0 | K225: 0 | L225: 236860.63 | M225: 1351354.4 | N225: 35046.24 | O225: 0 | P225: 6022.97 | Q225: 102100.16 | R225: 0 | S225: 0 | T225: =L225/12 -> 19738.386 | U225: =M225/12 -> 112612.87 | V225: =N225/12 -> 2920.52 | W225: =O225/12 -> 0 | X225: =P225/12 -> 501.91417 | Y225: =Q225/12 -> 8508.3467 | Z225: =R225/12 -> 0 | AA225: =S225/12 -> 0 | AB225: =T225+U225+V225+W225+X225+Y225+Z225+AA225 -> 144282.04 | AC225: =VLOOKUP(ПРОДАЖИ!C:C,'ИЗ ОСНОВЫ НОМЕНКЛАТУР'!D:E,2,0) -> Кромочные материалы | AD225: =VLOOKUP(C:C,'ИЗ ОСНОВЫ НОМЕНКЛАТУР'!D:F,3,0) -> Кромка ПВХ Китай | AE225: =VLOOKUP(C:C,'ИЗ ОСНОВЫ НОМЕНКЛАТУР'!D:H,5,0) -> B
A226: Кромочные материалы | C226: 19*1,5мм ПВХ Алюминий AN | D226: 3724 | E226: 500 | F226: 503 | G226: 12700 | H226: 0 | I226: 0 | J226: 0 | K226: 280 | L226: 179457.27 | M226: 24633.68 | N226: 28261.84 | O226: 628343.06 | P226: 0 | Q226: 0 | R226: 0 | S226: 13840.4 | T226: =L226/12 -> 14954.772 | U226: =M226/12 -> 2052.8067 | V226: =N226/12 -> 2355.1533 | W226: =O226/12 -> 52361.922 | X226: =P226/12 -> 0 | Y226: =Q226/12 -> 0 | Z226: =R226/12 -> 0 | AA226: =S226/12 -> 1153.3667 | AB226: =T226+U226+V226+W226+X226+Y226+Z226+AA226 -> 72878.021 | AC226: =VLOOKUP(ПРОДАЖИ!C:C,'ИЗ ОСНОВЫ НОМЕНКЛАТУР'!D:E,2,0) -> Кромочные материалы | AD226: =VLOOKUP(C:C,'ИЗ ОСНОВЫ НОМЕНКЛАТУР'!D:F,3,0) -> Кромка ПВХ Китай | AE226: =VLOOKUP(C:C,'ИЗ ОСНОВЫ НОМЕНКЛАТУР'!D:H,5,0) -> B
... A262: Кромочные материалы | C262: 19*1,5мм ПВХ Дуб честерфилд AN | D262: 100 | E262: 0 | F262: 0 | G262: 0 | H262: 0 | I262: 0 | J262: 0 | K262: 0 | L262: 5107.48 | M262: 0 | N262: 0 | O262: 0 | P262: 0 | Q262: 0 | R262: 0 | S262: 0 | T262: =L262/12 -> 425.62333 | U262: =M262/12 -> 0 | V262: =N262/12 -> 0 | W262: =O262/12 -> 0 | X262: =P262/12 -> 0 | Y262: =Q262/12 -> 0 | Z262: =R262/12 -> 0 | AA262: =S262/12 -> 0 | AB262: =T262+U262+V262+W262+X262+Y262+Z262+AA262 -> 425.62333 | AC262: =VLOOKUP(ПРОДАЖИ!C:C,'ИЗ ОСНОВЫ НОМЕНКЛАТУР'!D:E,2,0) -> Кромочные материалы | AD262: =VLOOKUP(C:C,'ИЗ ОСНОВЫ НОМЕНКЛАТУР'!D:F,3,0) -> Кромка ПВХ Китай | AE262: =VLOOKUP(C:C,'ИЗ ОСНОВЫ НОМЕНКЛАТУР'!D:H,5,0) -> C
A263: Кромочные материалы | B263: 36*1,5мм ПВХ | D263: 0 | E263: 0 | F263: 0 | G263: 0 | H263: 0 | I263: 0 | J263: 0 | K263: 0 | L263: 0 | M263: 0 | N263: 0 | O263: 0 | P263: 0 | Q263: 0 | R263: 0 | S263: 0 | T263: =L263/12 -> 0 | U263: =M263/12 -> 0 | V263: =N263/12 -> 0 | W263: =O263/12 -> 0 | X263: =P263/12 -> 0 | Y263: =Q263/12 -> 0 | Z263: =R263/12 -> 0 | AA263: =S263/12 -> 0 | AB263: =T263+U263+V263+W263+X263+Y263+Z263+AA263 -> 0 | AC263: =VLOOKUP(ПРОДАЖИ!C:C,'ИЗ ОСНОВЫ НОМЕНКЛАТУР'!D:E,2,0) -> #N/A | AD263: =VLOOKUP(C:C,'ИЗ ОСНОВЫ НОМЕНКЛАТУР'!D:F,3,0) -> #N/A | AE263: =VLOOKUP(C:C,'ИЗ ОСНОВЫ НОМЕНКЛАТУР'!D:H,5,0) -> #N/A
A264: Кромочные материалы | C264: 36*1,5мм ПВХ Белый AN | D264: 24065 | E264: 24800 | F264: 12387 | G264: 831 | H264: 2905 | I264: 19200 | J264: 100 | K264: 3960 | L264: 1654897.6 | M264: 1748562.6 | N264: 855020.8 | O264: 62911.15 | P264: 194991.87 | Q264: 1278322.4 | R264: 6214.56 | S264: 259940.77 | T264: =L264/12 -> 137908.13 | U264: =M264/12 -> 145713.55 | V264: =N264/12 -> 71251.733 | W264: =O264/12 -> 5242.5958 | X264: =P264/12 -> 16249.323 | Y264: =Q264/12 -> 106526.86 | Z264: =R264/12 -> 517.88 | AA264: =S264/12 -> 21661.731 | AB264: =T264+U264+V264+W264+X264+Y264+Z264+AA264 -> 505071.82 | AC264: =VLOOKUP(ПРОДАЖИ!C:C,'ИЗ ОСНОВЫ НОМЕНКЛАТУР'!D:E,2,0) -> Кромочные материалы | AD264: =VLOOKUP(C:C,'ИЗ ОСНОВЫ НОМЕНКЛАТУР'!D:F,3,0) -> Кромка ПВХ Китай | AE264: =VLOOKUP(C:C,'ИЗ ОСНОВЫ НОМЕНКЛАТУР'!D:H,5,0) -> A
A265: Кромочные материалы | C265: 36*1,5мм ПВХ Дуб Вотан AN | D265: 12313 | E265: 15730 | F265: 9102 | G265: 604 | H265: 3444 | I265: 3280 | J265: 200 | K265: 2983 | L265: 1040156.8 | M265: 1284804.6 | N265: 746359.65 | O265: 49404.53 | P265: 283158.5 | Q265: 253604.13 | R265: 16089.93 | S265: 236931.93 | T265: =L265/12 -> 86679.737 | U265: =M265/12 -> 107067.05 | V265: =N265/12 -> 62196.638 | W265: =O265/12 -> 4117.0442 | X265: =P265/12 -> 23596.542 | Y265: =Q265/12 -> 21133.678 | Z265: =R265/12 -> 1340.8275 | AA265: =S265/12 -> 19744.327 | AB265: =T265+U265+V265+W265+X265+Y265+Z265+AA265 -> 325875.85 | AC265: =VLOOKUP(ПРОДАЖИ!C:C,'ИЗ ОСНОВЫ НОМЕНКЛАТУР'!D:E,2,0) -> Кромочные материалы | AD265: =VLOOKUP(C:C,'ИЗ ОСНОВЫ НОМЕНКЛАТУР'!D:F,3,0) -> Кромка ПВХ Китай | AE265: =VLOOKUP(C:C,'ИЗ ОСНОВЫ НОМЕНКЛАТУР'!D:H,5,0) -> B
A266: Кромочные материалы | C266: 36*1,5мм ПВХ Дуб Сонома AN | D266: 11610 | E266: 6100 | F266: 6908 | G266: 1207 | H266: 3112 | I266: 6600 | J266: 200 | K266: 3684 | L266: 1061814.2 | M266: 556377.74 | N266: 629788.33 | O266: 110660.96 | P266: 271460.58 | Q266: 581567.59 | R266: 17423.21 | S266: 315212.74 | T266: =L266/12 -> 88484.514 | U266: =M266/12 -> 46364.812 | V266: =N266/12 -> 52482.361 | W266: =O266/12 -> 9221.7467 | X266: =P266/12 -> 22621.715 | Y266: =Q266/12 -> 48463.966 | Z266: =R266/12 -> 1451.9342 | AA266: =S266/12 -> 26267.728 | AB266: =T266+U266+V266+W266+X266+Y266+Z266+AA266 -> 295358.78 | AC266: =VLOOKUP(ПРОДАЖИ!C:C,'ИЗ ОСНОВЫ НОМЕНКЛАТУР'!D:E,2,0) -> Кромочные материалы | AD266: =VLOOKUP(C:C,'ИЗ ОСНОВЫ НОМЕНКЛАТУР'!D:F,3,0) -> Кромка ПВХ Китай | AE266: =VLOOKUP(C:C,'ИЗ ОСНОВЫ НОМЕНКЛАТУР'!D:H,5,0) -> B
A267: Кромочные материалы | C267: 36*1,5мм ПВХ Ясень шимо светлый AN | D267: 11696 | E267: 9000 | F267: 4307 | G267: 122 | H267: 992 | I267: 6800 | J267: 0 | K267: 2687 | L267: 1073493 | M267: 824760.38 | N267: 423183.48 | O267: 11321.36 | P267: 89294.12 | Q267: 606934.3 | R267: 0 | S267: 246631.13 | T267: =L267/12 -> 89457.752 | U267: =M267/12 -> 68730.032 | V267: =N267/12 -> 35265.29 | W267: =O267/12 -> 943.44667 | X267: =P267/12 -> 7441.1767 | Y267: =Q267/12 -> 50577.858 | Z267: =R267/12 -> 0 | AA267: =S267/12 -> 20552.594 | AB267: =T267+U267+V267+W267+X267+Y267+Z267+AA267 -> 272968.15 | AC267: =VLOOKUP(ПРОДАЖИ!C:C,'ИЗ ОСНОВЫ НОМЕНКЛАТУР'!D:E,2,0) -> Кромочные материалы | AD267: =VLOOKUP(C:C,'ИЗ ОСНОВЫ НОМЕНКЛАТУР'!D:F,3,0) -> Кромка ПВХ Китай | AE267: =VLOOKUP(C:C,'ИЗ ОСНОВЫ НОМЕНКЛАТУР'!D:H,5,0) -> B
A268: Кромочные материалы | C268: 36*1,5мм ПВХ Белый SJ | D268: 7642 | E268: 0 | F268: 1638 | G268: 1660 | H268: 1280 | I268: 1120 | J268: 0 | K268: 1500 | L268: 479642.43 | M268: 0 | N268: 102047.4 | O268: 105410 | P268: 79744 | Q268: 69776 | R268: 0 | S268: 93450 | T268: =L268/12 -> 39970.202 | U268: =M268/12 -> 0 | V268: =N268/12 -> 8503.95 | W268: =O268/12 -> 8784.1667 | X268: =P268/12 -> 6645.3333 | Y268: =Q268/12 -> 5814.6667 | Z268: =R268/12 -> 0 | AA268: =S268/12 -> 7787.5 | AB268: =T268+U268+V268+W268+X268+Y268+Z268+AA268 -> 77505.819 | AC268: =VLOOKUP(ПРОДАЖИ!C:C,'ИЗ ОСНОВЫ НОМЕНКЛАТУР'!D:E,2,0) -> Кромочные материалы | AD268: =VLOOKUP(C:C,'ИЗ ОСНОВЫ НОМЕНКЛАТУР'!D:F,3,0) -> Кромка ПВХ Китай | AE268: =VLOOKUP(C:C,'ИЗ ОСНОВЫ НОМЕНКЛАТУР'!D:H,5,0) -> B
A269: Кромочные материалы | C269: 36*1,5мм ПВХ Черный AN | D269: 9474 | E269: 2125 | F269: 8074 | G269: 168 | H269: 2518 | I269: 2160 | J269: 100 | K269: 1958 | L269: 785736.41 | M269: 176308.25 | N269: 665954.99 | O269: 14050.34 | P269: 208011.98 | Q269: 178437.6 | R269: 8219.84 | S269: 160686.17 | T269: =L269/12 -> 65478.034 | U269: =M269/12 -> 14692.354 | V269: =N269/12 -> 55496.249 | W269: =O269/12 -> 1170.8617 | X269: =P269/12 -> 17334.332 | Y269: =Q269/12 -> 14869.8 | Z269: =R269/12 -> 684.98667 | AA269: =S269/12 -> 13390.514 | AB269: =T269+U269+V269+W269+X269+Y269+Z269+AA269 -> 183117.13 | AC269: =VLOOKUP(ПРОДАЖИ!C:C,'ИЗ ОСНОВЫ НОМЕНКЛАТУР'!D:E,2,0) -> Кромочные материалы | AD269: =VLOOKUP(C:C,'ИЗ ОСНОВЫ НОМЕНКЛАТУР'!D:F,3,0) -> Кромка ПВХ Китай | AE269: =VLOOKUP(C:C,'ИЗ ОСНОВЫ НОМЕНКЛАТУР'!D:H,5,0) -> B
...

Sheet ОБОРАЧИВ ПО СЕТИ+ABC
I1: A | M1: B | Q1: C
A2: КАТЕГОРИИ | B2: ПРОДАЖА ПО Себ.Ст | D2: ОСТАТОК по Себ.Ст. | F2: ОБОРАЧИВАЕМОСТЬ (дн.) | I2: ПРОД | J2: ОСТАТ | K2: % | L2: ОБОР | M2: ПРОД | N2: ОСТАТ | O2: % | P2: ОБОР | Q2: ПРОД | R2: ОСТАТ | S2: % | T2: ОБОР
